Workbook
Name ALEMANIA: Recursos!$B$1
Name ARABIA_SAUDITA: Recursos!$B$2
Name ARGELIA: Recursos!$B$3
Name ARGENTINA: Recursos!$B$4
Name AUSTRALIA: Recursos!$B$5
Name AUSTRIA: Recursos!$B$6
Name BÉLGICA: Recursos!$B$7
Name BOSNIA_y_HERZEG.: Recursos!$B$8
Name BRASIL: Recursos!$B$9
Name CABO_VERDE: Recursos!$B$10
Name CANADÁ: Recursos!$B$11
Name CATAR: Recursos!$B$12
Name clave: Recursos!$AD$2
Name claveN: Recursos!$AD$3
Name CoefUTCD: UTC!$AA$3
Name COLOMBIA: Recursos!$B$13
Name COREA_del_SUR: Recursos!$B$14
Name COSTA_de_MARFIL: Recursos!$B$15
Name CROACIA: Recursos!$B$16
Name CURAZAO: Recursos!$B$17
Name ECUADOR: Recursos!$B$18
Name EGIPTO: Recursos!$B$20
Name ESCOCIA: Recursos!$B$21
Name ESPAÑA: Recursos!$B$22
Name ESTADOS_UNIDOS: Recursos!$B$19
Name flag01: INDIRECT(Dieciseisavos!$E$8)
Name flag02: INDIRECT(Dieciseisavos!$E$12)
Name flag03: INDIRECT(Dieciseisavos!$E$16)
Name flag04: INDIRECT(Dieciseisavos!$E$20)
Name flag05: INDIRECT(Dieciseisavos!$E$24)
Name flag06: INDIRECT(Dieciseisavos!$E$28)
Name flag07: INDIRECT(Dieciseisavos!$E$32)
Name flag08: INDIRECT(Dieciseisavos!$E$36)
Name flag09: INDIRECT(Dieciseisavos!$E$40)
Name flag10: INDIRECT(Dieciseisavos!$E$44)
Name flag11: INDIRECT(Dieciseisavos!$E$48)
Name flag12: INDIRECT(Dieciseisavos!$E$52)
Name flag13: INDIRECT(Dieciseisavos!$E$56)
Name flag14: INDIRECT(Dieciseisavos!$E$60)
Name flag15: INDIRECT(Dieciseisavos!$E$64)
Name flag16: INDIRECT(Dieciseisavos!$E$68)
Name flag17: INDIRECT(Dieciseisavos!$O$8)
Name flag18: INDIRECT(Dieciseisavos!$O$12)
Name flag19: INDIRECT(Dieciseisavos!$O$16)
Name flag20: INDIRECT(Dieciseisavos!$O$20)
Name flag21: INDIRECT(Dieciseisavos!$O$24)
Name flag22: INDIRECT(Dieciseisavos!$O$28)
Name flag23: INDIRECT(Dieciseisavos!$O$32)
Name flag24: INDIRECT(Dieciseisavos!$O$36)
Name flag25: INDIRECT(Dieciseisavos!$O$40)
Name flag26: INDIRECT(Dieciseisavos!$O$44)
Name flag27: INDIRECT(Dieciseisavos!$O$48)
Name flag28: INDIRECT(Dieciseisavos!$O$52)
Name flag29: INDIRECT(Dieciseisavos!$O$56)
Name flag30: INDIRECT(Dieciseisavos!$O$60)
Name flag31: INDIRECT(Dieciseisavos!$O$64)
Name flag32: INDIRECT(Dieciseisavos!$O$68)
Name flag33: INDIRECT(Octavos!$E$8)
Name flag34: INDIRECT(Octavos!$E$12)
Name flag35: INDIRECT(Octavos!$E$16)

Sheet Portada
XFD1: =Copyright!XFC1 -> 1

Sheet Ingreso
D5: Los horarios de los partidos corresponden a la localidad donde se juega el encuentro.
D6: =TEXT(VLOOKUP(B8,tDatos[],IF(UTCElegido="",3,12),0),"dddd dd mmmm") -> jueves 11 junio
B8: 1 | C8: 1 | E8: =VLOOKUP(B8,tDatos[],IF(UTCElegido="",4,12),0) -> 0.625
F9: MÉXICO | I9: - | L9: SUDÁFRICA
I10: Estadio Ciudad de México
D12: =TEXT(VLOOKUP(B14,tDatos[],IF(UTCElegido="",3,12),0),"dddd dd mmmm") -> jueves 11 junio
B14: 2 | C14: 2 | E14: =VLOOKUP(B14,tDatos[],IF(UTCElegido="",4,12),0) -> 0.91666667
F15: COREA del SUR | I15: - | L15: REP. CHECA
I16: Estadio Guadalajara
D18: =TEXT(VLOOKUP(B20,tDatos[],IF(UTCElegido="",3,12),0),"dddd dd mmmm") -> viernes 12 junio
B20: 3 | C20: 3 | E20: =VLOOKUP(B20,tDatos[],IF(UTCElegido="",4,12),0) -> 0.625
F21: CANADÁ | I21: - | L21: BOSNIA Y HERZEG.
I22: Estadio Toronto
D24: =TEXT(VLOOKUP(B26,tDatos[],IF(UTCElegido="",3,12),0),"dddd dd mmmm") -> viernes 12 junio
B26: 4 | C26: 4 | E26: =VLOOKUP(B26,tDatos[],IF(UTCElegido="",4,12),0) -> 0.875
F27: ESTADOS UNIDOS | I27: - | L27: PARAGUAY
I28: Estadio Los Angeles
D30: =TEXT(VLOOKUP(B32,tDatos[],IF(UTCElegido="",3,12),0),"dddd dd mmmm") -> sábado 13 junio
B32: 5 | C32: 8 | E32: =VLOOKUP(B32,tDatos[],IF(UTCElegido="",4,12),0) -> 0.625
F33: CATAR | I33: - | L33: SUIZA
I34: Estadio Bahía de San Francisco
D36: =TEXT(VLOOKUP(B38,tDatos[],IF(UTCElegido="",3,12),0),"dddd dd mmmm") -> sábado 13 junio
B38: 6 | C38: 7 | E38: =VLOOKUP(B38,tDatos[],IF(UTCElegido="",4,12),0) -> 0.75
F39: BRASIL | I39: - | L39: MARRUECOS
I40: Estadio Nueva York/Nueva Jersey
D42: =TEXT(VLOOKUP(B44,tDatos[],IF(UTCElegido="",3,12),0),"dddd dd mmmm") -> sábado 13 junio
B44: 7 | C44: 5 | E44: =VLOOKUP(B44,tDatos[],IF(UTCElegido="",4,12),0) -> 0.875
F45: HAITÍ | I45: - | L45: ESCOCIA
I46: Estadio Boston
D48: =TEXT(VLOOKUP(B50,tDatos[],IF(UTCElegido="",3,12),0),"dddd dd mmmm") -> domingo 14 junio
B50: 8 | C50: 6 | E50: =VLOOKUP(B50,tDatos[],IF(UTCElegido="",4,12),0) -> 0
F51: AUSTRALIA | I51: - | L51: TURQUÍA
I52: Estadio BC Place Vancouver
D54: =TEXT(VLOOKUP(B56,tDatos[],IF(UTCElegido="",3,12),0),"dddd dd mmmm") -> domingo 14 junio
B56: 9 | C56: 10 | E56: =VLOOKUP(B56,tDatos[],IF(UTCElegido="",4,12),0) -> 0.54166667
F57: ALEMANIA | I57: - | L57: CURAZAO
I58: Estadio Houston
D60: =TEXT(VLOOKUP(B62,tDatos[],IF(UTCElegido="",3,12),0),"dddd dd mmmm") -> domingo 14 junio
B62: 10 | C62: 11 | E62: =VLOOKUP(B62,tDatos[],IF(UTCElegido="",4,12),0) -> 0.66666667
F63: PAÍSES BAJOS | I63: - | L63: JAPÓN
...

Sheet A
AK1: =IFERROR(K8+K20+I24,0) -> 1
B5: Los horarios de los partidos corresponden a la localidad donde se juega el encuentro.
B6: # | C6: Fechas | D6: Horas | E6: PARTIDOS | P6: Estadios | R6: POSICIONES | AO6: =COUNT(I8,K8,I12,K12,I16,K16,I20,K20,I24,K24,I28,K28) -> 12 | AP6: =(AN10=AN15)+(AN15=AN20)+(AN20=AN25)+(AN10=AN20)+(AN15=AN25)+(AN10=AN25) -> 0 | AR6: Partido | AS6: Ganador | AT6: 1 | AU6: 2 | AV6: Dif. | AX6: =(AX10=AX15)+(AX15=AX20)+(AX20=AX25)+(AX10=AX20)+(AX15=AX25)+(AX10=AX25) -> 0 | BB6: =(BB10=BB15)+(BB15=BB20)+(BB20=BB25)+(BB10=BB20)+(BB15=BB25)+(BB10=BB25) -> 0
AC7: Puntos
A8: 1 | B8: 1 | C8: =VLOOKUP(A8,tDatos[],IF(UTCElegido="",3,12),0) -> 46184 | D8: =VLOOKUP(A8,tDatos[],IF(UTCElegido="",4,12),0) -> 0.625 | F8: =VLOOKUP(A8,tDatos[],5,0) -> MÉXICO | G8: =IF(OR(I8="",K8=""),"",IF(I8=K8,"E",IF(I8>K8,"G","P"))) -> G | I8: 2 | J8: - | K8: 1 | L8: =IF(OR(K8="",I8=""),"",IF(K8=I8,"E",IF(K8>I8,"G","P"))) -> P | N8: =VLOOKUP(A8,tDatos[],6,0) -> SUDÁFRICA | P8: =VLOOKUP(A8,tDatos[],9,0) -> Ciudad de México | V8: Jug. | W8: Gan. | X8: Emp. | Y8: Per. | Z8: GF | AA8: GC | AB8: DG | AG8: Jug. | AH8: Gan. | AI8: Emp. | AJ8: Per. | AK8: GF | AL8: GC | AM8: Dif. | AN8: Pts. | AR8: =F8&N8 -> MÉXICOSUDÁFRICA | AS8: =IF(I8>K8,F8,IF(K8>I8,N8,"")) -> MÉXICO | AT8: =I8 -> 2 | AU8: =K8 -> 1 | AV8: =AT8-AU8 -> 1
AR9: =N8&F8 -> SUDÁFRICAMÉXICO | AS9: =IF(I8>K8,F8,IF(K8>I8,N8,"")) -> MÉXICO | AT9: =K8 -> 1 | AU9: =I8 -> 2 | AV9: =AT9-AU9 -> -1
R10: =" 1) " & VLOOKUP(1,$AE$10:$AF$29,2,0) -> 1) MÉXICO | V10: =VLOOKUP(1,$AE$10:$AG$29,3,0) -> 3 | W10: =VLOOKUP(1,$AE$10:$AH$29,4,0) -> 3 | X10: =VLOOKUP(1,$AE$10:$AI$29,5,0) -> 0 | Y10: =VLOOKUP(1,$AE$10:$AJ$29,6,0) -> 0 | Z10: =VLOOKUP(1,$AE$10:$AK$29,7,0) -> 4 | AA10: =VLOOKUP(1,$AE$10:$AL$29,8,0) -> 1 | AB10: =Z10-AA10 -> 3 | AC10: =(W10*3)+X10 -> 9 | AD10: =RANK(AO10,$AO$10:$AO$29,0) -> 1 | AE10: =RANK(AP10,$AP$10:$AP$29,1) -> 1 | AF10: =F8 -> MÉXICO | AG10: =3-COUNTIF(I32:K32,"") -> 3 | AH10: =COUNTIF(I32:K32,"G") -> 3 | AI10: =COUNTIF(I32:K32,"E") -> 0 | AJ10: =COUNTIF(I32:K32,"P") -> 0 | AK10: =SUM(I8,I20,K24) -> 4 | AL10: =SUM(K8,K20,I24) -> 1 | AM10: =AK10-AL10 -> 3 | AN10: =(AH10*3)+AI10*vcp -> 9 | AO10: =IF($AO$6>0,AN10*10+3) -> 93 | AP10: =IF(AF10=$R$38,BF10-100,IF(AF10=$R$37,BF10-200,IF(AF10=$R$36,BF10-300,BF10))) -> -299 | AQ10: =IF(R36="",IF(SUM($V$10:$V$29)>0,VLOOKUP(1,$AE$10:$AF$29,2,0),""),R36) -> MÉXICO | AW10: =RANK(AY10,$AY$10:$AY$29,0) -> 1 | AX10: =IF(AND($AO$6>0,$AP$6>0),AN10*10000+AZ10,AO10) -> 93 | AY10: =IF(AND($AO$6>0,$AP$6>0),AN10*10000+AZ10,AO10) -> 93 | AZ10: =--IF(AND($AO$6>0,$AP$6>0), _xlfn.IFNA(IF(AN10=VLOOKUP(1,$AD$10:$AN$29,11,0),IF(VLOOKUP(AF10&VLOOKUP(1,$AD$10:$AN$29,3,0),$AR$8:$AS$29,2,0)=AF10,1000)),0)+ _xlfn.IFNA(IF(AN10=VLOOKUP(2,$AD$10:$AN$29,11,0),IF(VLOOKUP(AF10&VLOOKUP(2,$AD$10:$AN$29,3,0),$AR$8:$AS$29,2,0)=AF10,1000)),0)+ _xlfn.IFNA(IF(AN10=VLOOKUP(3,$AD$10:$AN$29,11,0),IF(VLOOKUP(AF10&VLOOKUP(3,$AD$10:$AN$29,3,0),$AR$8:$AS$29,2,0)=AF10,1000)),0)+ _xlfn.IFNA(IF(AN10=VLOOKUP(4,$AD$10:$AN$29,11,0),IF(VLOOKUP(AF10&VLOOKUP(4,$AD$10:$AN$29,3,0),$AR$8:$AS$29,2,0)=AF10,1000)),0)) -> 0 | BA10: =RANK(BB10,$BB$10:$BB$29,0) -> 1 | BB10: =AX10+BD10 -> 93 | BC10: =AX10+BD10+3 -> 96 | BD10: =--IF(AND($AO$6>0,$AX$6>0), _xlfn.IFNA(IF(AX10=VLOOKUP(1,$AW$10:$AX$29,2,0),IF(VLOOKUP(AF10&VLOOKUP(1,$AD$10:$AX$29,3,0),$AR$8:$AV$29,2,0)=AF10,VLOOKUP(AF10&VLOOKUP(1,$AD$10:$AX$29,3,0),$AR$8:$AV$29,5,0)*100+VLOOKUP(AF10&VLOOKUP(1,$AD$10:$AX$29,3,0),$AR$8:$AV$29,3,0)*10)),0)+ _xlfn.IFNA(IF(AX10=VLOOKUP(2,$AW$10:$AX$29,2,0),IF(VLOOKUP(AF10&VLOOKUP(2,$AD$10:$AX$29,3,0),$AR$8:$AV$29,2,0)=AF10,VLOOKUP(AF10&VLOOKUP(2,$AD$10:$AX$29,3,0),$AR$8:$AV$29,5,0)*100+VLOOKUP(AF10&VLOOKUP(2,$AD$10:$AX$29,3,0),$AR$8:$AV$29,3,0)*10)),0)+ _xlfn.IFNA(IF(AX10=VLOOKUP(3,$AW$10:$AX$29,2,0),IF(VLOOKUP(AF10&VLOOKUP(3,$AD$10:$AX$29,3,0),$AR$8:$AV$29,2,0)=AF10,VLOOKUP(AF10&VLOOKUP(3,$AD$10:$AX$29,3,0),$AR$8:$AV$29,5,0)*100+VLOOKUP(AF10&VLOOKUP(3,$AD$10:$AX$29,3,0),$AR$8:$AV$29,3,0)*10)),0)+ _xlfn.IFNA(IF(AX10=VLOOKUP(4,$AW$10:$AX$29,2,0),IF(VLOOKUP(AF10&VLOOKUP(4,$AD$10:$AX$29,3,0),$AR$8:$AV$29,2,0)=AF10,VLOOKUP(AF10&VLOOKUP(4,$AD$10:$AX$29,3,0),$AR$8:$AV$29,5,0)*100+VLOOKUP(AF10&VLOOKUP(4,$AD$10:$AX$29,3,0),$AR$8:$AV$29,3,0)*10)),0)) -> 0 | BE10: =(IF(AND($AO$6>0,$BB$6>0),AN10*1000+AM10*100+AK10*10,0)+3)/100+BB10 -> 93.03 | BF10: =RANK(BE10,$BE$10:$BE$29) -> 1 | BG10: =BE10-0.03 -> 93 | BH10: =COUNTIF($BG$10:$BG$29,BG10) -> 1
A12: 2 | B12: 2 | C12: =VLOOKUP(A12,tDatos[],IF(UTCElegido="",3,12),0) -> 46184 | D12: =VLOOKUP(A12,tDatos[],IF(UTCElegido="",4,12),0) -> 0.91666667 | F12: =VLOOKUP(A12,tDatos[],5,0) -> COREA del SUR | G12: =IF(OR(I12="",K12=""),"",IF(I12=K12,"E",IF(I12>K12,"G","P"))) -> E | I12: 1 | J12: - | K12: 1 | L12: =IF(OR(K12="",I12=""),"",IF(K12=I12,"E",IF(K12>I12,"G","P"))) -> E | N12: =VLOOKUP(A12,tDatos[],6,0) -> REP. CHECA | P12: =VLOOKUP(A12,tDatos[],9,0) -> Guadalajara | AR12: =F12&N12 -> COREA del SURREP. CHECA | AS12: =IF(I12>K12,F12,IF(K12>I12,N12,"")) | AT12: =I12 -> 1 | AU12: =K12 -> 1 | AV12: =AT12-AU12 -> 0
AR13: =N12&F12 -> REP. CHECACOREA del SUR | AS13: =IF(I12>K12,F12,IF(K12>I12,N12,"")) | AT13: =K12 -> 1 | AU13: =I12 -> 1 | AV13: =AT13-AU13 -> 0
R15: =" 2) " & VLOOKUP(2,$AE$10:$AF$29,2,0) -> 2) REP. CHECA | V15: =VLOOKUP(2,$AE$10:$AG$29,3,0) -> 3 | W15: =VLOOKUP(2,$AE$10:$AH$29,4,0) -> 1 | X15: =VLOOKUP(2,$AE$10:$AI$29,5,0) -> 1 | Y15: =VLOOKUP(2,$AE$10:$AJ$29,6,0) -> 1 | Z15: =VLOOKUP(2,$AE$10:$AK$29,7,0) -> 2 | AA15: =VLOOKUP(2,$AE$10:$AL$29,8,0) -> 2 | AB15: =Z15-AA15 -> 0 | AC15: =(W15*3)+X15 -> 4 | AD15: =RANK(AO15,$AO$10:$AO$29,0) -> 3 | AE15: =RANK(AP15,$AP$10:$AP$29,1) -> 3 | AF15: =N8 -> SUDÁFRICA | AG15: =3-COUNTIF(I33:K33,"") -> 3 | AH15: =COUNTIF(I33:K33,"G") -> 1 | AI15: =COUNTIF(I33:K33,"E") -> 0 | AJ15: =COUNTIF(I33:K33,"P") -> 2 | AK15: =SUM(K8,K16,I28) -> 3 | AL15: =SUM(I8,I16,K28) -> 3 | AM15: =AK15-AL15 -> 0 | AN15: =(AH15*3)+AI15*vcp -> 3 | AO15: =IF($AO$6>0,AN15*10+2) -> 32 | AP15: =IF(AF15=$R$38,BF15-100,IF(AF15=$R$37,BF15-200,IF(AF15=$R$36,BF15-300,BF15))) -> -97 | AQ15: =IF(R37="",IF(SUM($V$10:$V$29)>0,VLOOKUP(2,$AE$10:$AF$29,2,0),""),R37) -> REP. CHECA | AW15: =RANK(AY15,$AY$10:$AY$29,0) -> 3 | AX15: =IF(AND($AO$6>0,$AP$6>0),AN15*10000+AZ15,AO15) -> 32 | AY15: =IF(AND($AO$6>0,$AP$6>0),AN15*10000+AZ15-1,AO15) -> 32 | AZ15: =--IF(AND($AO$6>0,$AP$6>0), _xlfn.IFNA(IF(AN15=VLOOKUP(1,$AD$10:$AN$29,11,0),IF(VLOOKUP(AF15&VLOOKUP(1,$AD$10:$AN$29,3,0),$AR$8:$AS$29,2,0)=AF15,1000)),0)+ _xlfn.IFNA(IF(AN15=VLOOKUP(2,$AD$10:$AN$29,11,0),IF(VLOOKUP(AF15&VLOOKUP(2,$AD$10:$AN$29,3,0),$AR$8:$AS$29,2,0)=AF15,1000)),0)+ _xlfn.IFNA(IF(AN15=VLOOKUP(3,$AD$10:$AN$29,11,0),IF(VLOOKUP(AF15&VLOOKUP(3,$AD$10:$AN$29,3,0),$AR$8:$AS$29,2,0)=AF15,1000)),0)+ _xlfn.IFNA(IF(AN15=VLOOKUP(4,$AD$10:$AN$29,11,0),IF(VLOOKUP(AF15&VLOOKUP(4,$AD$10:$AN$29,3,0),$AR$8:$AS$29,2,0)=AF15,1000)),0)) -> 0 | BA15: =RANK(BB15,$BB$10:$BB$29,0) -> 3 | BB15: =AX15+BD15 -> 32 | BC15: =AX15+BD15+2 -> 34 | BD15: =--IF(AND($AO$6>0,$AX$6>0), _xlfn.IFNA(IF(AX15=VLOOKUP(1,$AW$10:$AX$29,2,0),IF(VLOOKUP(AF15&VLOOKUP(1,$AD$10:$AX$29,3,0),$AR$8:$AV$29,2,0)=AF15,VLOOKUP(AF15&VLOOKUP(1,$AD$10:$AX$29,3,0),$AR$8:$AV$29,5,0)*100+VLOOKUP(AF15&VLOOKUP(1,$AD$10:$AX$29,3,0),$AR$8:$AV$29,3,0)*10)),0)+ _xlfn.IFNA(IF(AX15=VLOOKUP(2,$AW$10:$AX$29,2,0),IF(VLOOKUP(AF15&VLOOKUP(2,$AD$10:$AX$29,3,0),$AR$8:$AV$29,2,0)=AF15,VLOOKUP(AF15&VLOOKUP(2,$AD$10:$AX$29,3,0),$AR$8:$AV$29,5,0)*100+VLOOKUP(AF15&VLOOKUP(2,$AD$10:$AX$29,3,0),$AR$8:$AV$29,3,0)*10)),0)+ _xlfn.IFNA(IF(AX15=VLOOKUP(3,$AW$10:$AX$29,2,0),IF(VLOOKUP(AF15&VLOOKUP(3,$AD$10:$AX$29,3,0),$AR$8:$AV$29,2,0)=AF15,VLOOKUP(AF15&VLOOKUP(3,$AD$10:$AX$29,3,0),$AR$8:$AV$29,5,0)*100+VLOOKUP(AF15&VLOOKUP(3,$AD$10:$AX$29,3,0),$AR$8:$AV$29,3,0)*10)),0)+ _xlfn.IFNA(IF(AX15=VLOOKUP(4,$AW$10:$AX$29,2,0),IF(VLOOKUP(AF15&VLOOKUP(4,$AD$10:$AX$29,3,0),$AR$8:$AV$29,2,0)=AF15,VLOOKUP(AF15&VLOOKUP(4,$AD$10:$AX$29,3,0),$AR$8:$AV$29,5,0)*100+VLOOKUP(AF15&VLOOKUP(4,$AD$10:$AX$29,3,0),$AR$8:$AV$29,3,0)*10)),0)) -> 0 | BE15: =(IF(AND($AO$6>0,$BB$6>0),AN15*1000+AM15*100+AK15*10,0)+2)/100+BB15 -> 32.02 | BF15: =RANK(BE15,$BE$10:$BE$29) -> 3 | BG15: =BE15-0.02 -> 32 | BH15: =COUNTIF($BG$10:$BG$29,BG15) -> 1
A16: 25 | B16: 25 | C16: =VLOOKUP(A16,tDatos[],IF(UTCElegido="",3,12),0) -> 46191 | D16: =VLOOKUP(A16,tDatos[],IF(UTCElegido="",4,12),0) -> 0.5 | F16: =VLOOKUP(A16,tDatos[],5,0) -> REP. CHECA | G16: =IF(OR(I16="",K16=""),"",IF(I16=K16,"E",IF(I16>K16,"G","P"))) -> G | I16: 1 | J16: - | K16: 0 | L16: =IF(OR(K16="",I16=""),"",IF(K16=I16,"E",IF(K16>I16,"G","P"))) -> P | N16: =VLOOKUP(A16,tDatos[],6,0) -> SUDÁFRICA | P16: =VLOOKUP(A16,tDatos[],9,0) -> Atlanta | AR16: =F16&N16 -> REP. CHECASUDÁFRICA | AS16: =IF(I16>K16,F16,IF(K16>I16,N16,"")) -> REP. CHECA | AT16: =I16 -> 1 | AU16: =K16 -> 0 | AV16: =AT16-AU16 -> 1
AR17: =N16&F16 -> SUDÁFRICAREP. CHECA | AS17: =IF(I16>K16,F16,IF(K16>I16,N16,"")) -> REP. CHECA | AT17: =K16 -> 0 | AU17: =I16 -> 1 | AV17: =AT17-AU17 -> -1
A20: 28 | B20: 28 | C20: =VLOOKUP(A20,tDatos[],IF(UTCElegido="",3,12),0) -> 46191 | D20: =VLOOKUP(A20,tDatos[],IF(UTCElegido="",4,12),0) -> 0.875 | F20: =VLOOKUP(A20,tDatos[],5,0) -> MÉXICO | G20: =IF(OR(I20="",K20=""),"",IF(I20=K20,"E",IF(I20>K20,"G","P"))) -> G | I20: 1 | J20: - | K20: 0 | L20: =IF(OR(K20="",I20=""),"",IF(K20=I20,"E",IF(K20>I20,"G","P"))) -> P | N20: =VLOOKUP(A20,tDatos[],6,0) -> COREA del SUR | P20: =VLOOKUP(A20,tDatos[],9,0) -> Guadalajara | R20: =" 3) " & VLOOKUP(3,$AE$10:$AF$29,2,0) -> 3) SUDÁFRICA | V20: =VLOOKUP(3,$AE$10:$AG$29,3,0) -> 3 | W20: =VLOOKUP(3,$AE$10:$AH$29,4,0) -> 1 | X20: =VLOOKUP(3,$AE$10:$AI$29,5,0) -> 0 | Y20: =VLOOKUP(3,$AE$10:$AJ$29,6,0) -> 2 | Z20: =VLOOKUP(3,$AE$10:$AK$29,7,0) -> 3 | AA20: =VLOOKUP(3,$AE$10:$AL$29,8,0) -> 3 | AB20: =Z20-AA20 -> 0 | AC20: =(W20*3)+X20 -> 3 | AD20: =RANK(AO20,$AO$10:$AO$29,0) -> 4 | AE20: =RANK(AP20,$AP$10:$AP$29,1) -> 4 | AF20: =F12 -> COREA del SUR | AG20: =3-COUNTIF(I34:K34,"") -> 3 | AH20: =COUNTIF(I34:K34,"G") -> 0 | AI20: =COUNTIF(I34:K34,"E") -> 1 | AJ20: =COUNTIF(I34:K34,"P") -> 2 | AK20: =SUM(I12,K20,K28) -> 1 | AL20: =SUM(K12,I20,I28) -> 4 | AM20: =AK20-AL20 -> -3 | AN20: =(AH20*3)+AI20*vcp -> 1 | AO20: =IF($AO$6>0,AN20*10+1) -> 11 | AP20: =IF(AF20=$R$38,BF20-100,IF(AF20=$R$37,BF20-200,IF(AF20=$R$36,BF20-300,BF20))) -> 4 | AQ20: =IF(R38="",IF(SUM($V$10:$V$29)>0,VLOOKUP(3,$AE$10:$AF$29,2,0),""),R38) -> SUDÁFRICA | AR20: =F20&N20 -> MÉXICOCOREA del SUR | AS20: =IF(I20>K20,F20,IF(K20>I20,N20,"")) -> MÉXICO | AT20: =I20 -> 1 | AU20: =K20 -> 0 | AV20: =AT20-AU20 -> 1 | AW20: =RANK(AY20,$AY$10:$AY$29,0) -> 4 | AX20: =IF(AND($AO$6>0,$AP$6>0),AN20*10000+AZ20,AO20) -> 11 | AY20: =IF(AND($AO$6>0,$AP$6>0),AN20*10000+AZ20-2,AO20) -> 11 | AZ20: =--IF(AND($AO$6>0,$AP$6>0), _xlfn.IFNA(IF(AN20=VLOOKUP(1,$AD$10:$AN$29,11,0),IF(VLOOKUP(AF20&VLOOKUP(1,$AD$10:$AN$29,3,0),$AR$8:$AS$29,2,0)=AF20,1000)),0)+ _xlfn.IFNA(IF(AN20=VLOOKUP(2,$AD$10:$AN$29,11,0),IF(VLOOKUP(AF20&VLOOKUP(2,$AD$10:$AN$29,3,0),$AR$8:$AS$29,2,0)=AF20,1000)),0)+ _xlfn.IFNA(IF(AN20=VLOOKUP(3,$AD$10:$AN$29,11,0),IF(VLOOKUP(AF20&VLOOKUP(3,$AD$10:$AN$29,3,0),$AR$8:$AS$29,2,0)=AF20,1000)),0)+ _xlfn.IFNA(IF(AN20=VLOOKUP(4,$AD$10:$AN$29,11,0),IF(VLOOKUP(AF20&VLOOKUP(4,$AD$10:$AN$29,3,0),$AR$8:$AS$29,2,0)=AF20,1000)),0)) -> 0 | BA20: =RANK(BB20,$BB$10:$BB$29,0) -> 4 | BB20: =AX20+BD20 -> 11 | BC20: =AX20+BD20+1 -> 12 | BD20: =--IF(AND($AO$6>0,$AX$6>0), _xlfn.IFNA(IF(AX20=VLOOKUP(1,$AW$10:$AX$29,2,0),IF(VLOOKUP(AF20&VLOOKUP(1,$AD$10:$AX$29,3,0),$AR$8:$AV$29,2,0)=AF20,VLOOKUP(AF20&VLOOKUP(1,$AD$10:$AX$29,3,0),$AR$8:$AV$29,5,0)*100+VLOOKUP(AF20&VLOOKUP(1,$AD$10:$AX$29,3,0),$AR$8:$AV$29,3,0)*10)),0)+ _xlfn.IFNA(IF(AX20=VLOOKUP(2,$AW$10:$AX$29,2,0),IF(VLOOKUP(AF20&VLOOKUP(2,$AD$10:$AX$29,3,0),$AR$8:$AV$29,2,0)=AF20,VLOOKUP(AF20&VLOOKUP(2,$AD$10:$AX$29,3,0),$AR$8:$AV$29,5,0)*100+VLOOKUP(AF20&VLOOKUP(2,$AD$10:$AX$29,3,0),$AR$8:$AV$29,3,0)*10)),0)+ _xlfn.IFNA(IF(AX20=VLOOKUP(3,$AW$10:$AX$29,2,0),IF(VLOOKUP(AF20&VLOOKUP(3,$AD$10:$AX$29,3,0),$AR$8:$AV$29,2,0)=AF20,VLOOKUP(AF20&VLOOKUP(3,$AD$10:$AX$29,3,0),$AR$8:$AV$29,5,0)*100+VLOOKUP(AF20&VLOOKUP(3,$AD$10:$AX$29,3,0),$AR$8:$AV$29,3,0)*10)),0)+ _xlfn.IFNA(IF(AX20=VLOOKUP(4,$AW$10:$AX$29,2,0),IF(VLOOKUP(AF20&VLOOKUP(4,$AD$10:$AX$29,3,0),$AR$8:$AV$29,2,0)=AF20,VLOOKUP(AF20&VLOOKUP(4,$AD$10:$AX$29,3,0),$AR$8:$AV$29,5,0)*100+VLOOKUP(AF20&VLOOKUP(4,$AD$10:$AX$29,3,0),$AR$8:$AV$29,3,0)*10)),0)) -> 0 | BE20: =(IF(AND($AO$6>0,$BB$6>0),AN20*1000+AM20*100+AK20*10,0)+1)/100+BB20 -> 11.01 | BF20: =RANK(BE20,$BE$10:$BE$29) -> 4 | BG20: =BE20-0.01 -> 11 | BH20: =COUNTIF($BG$10:$BG$29,BG20) -> 1
AR21: =N20&F20 -> COREA del SURMÉXICO | AS21: =IF(I20>K20,F20,IF(K20>I20,N20,"")) -> MÉXICO | AT21: =K20 -> 0 | AU21: =I20 -> 1 | AV21: =AT21-AU21 -> -1
A24: 53 | B24: 53 | C24: =VLOOKUP(A24,tDatos[],IF(UTCElegido="",3,12),0) -> 46197 | D24: =VLOOKUP(A24,tDatos[],IF(UTCElegido="",4,12),0) -> 0.875 | F24: =VLOOKUP(A24,tDatos[],5,0) -> REP. CHECA | G24: =IF(OR(I24="",K24=""),"",IF(I24=K24,"E",IF(I24>K24,"G","P"))) -> P | I24: 0 | J24: - | K24: 1 | L24: =IF(OR(K24="",I24=""),"",IF(K24=I24,"E",IF(K24>I24,"G","P"))) -> G | N24: =VLOOKUP(A24,tDatos[],6,0) -> MÉXICO | P24: =VLOOKUP(A24,tDatos[],9,0) -> Ciudad de México | AR24: =F24&N24 -> REP. CHECAMÉXICO | AS24: =IF(I24>K24,F24,IF(K24>I24,N24,"")) -> MÉXICO | AT24: =I24 -> 0 | AU24: =K24 -> 1 | AV24: =AT24-AU24 -> -1
R25: =" 4) " & VLOOKUP(4,$AE$10:$AF$29,2,0) -> 4) COREA del SUR | V25: =VLOOKUP(4,$AE$10:$AG$29,3,0) -> 3 | W25: =VLOOKUP(4,$AE$10:$AH$29,4,0) -> 0 | X25: =VLOOKUP(4,$AE$10:$AI$29,5,0) -> 1 | Y25: =VLOOKUP(4,$AE$10:$AJ$29,6,0) -> 2 | Z25: =VLOOKUP(4,$AE$10:$AK$29,7,0) -> 1 | AA25: =VLOOKUP(4,$AE$10:$AL$29,8,0) -> 4 | AB25: =Z25-AA25 -> -3 | AC25: =(W25*3)+X25 -> 1 | AD25: =RANK(AO25,$AO$10:$AO$29,0) -> 2 | AE25: =RANK(AP25,$AP$10:$AP$29,1) -> 2 | AF25: =N12 -> REP. CHECA | AG25: =3-COUNTIF(I35:K35,"") -> 3 | AH25: =COUNTIF(I35:K35,"G") -> 1 | AI25: =COUNTIF(I35:K35,"E") -> 1 | AJ25: =COUNTIF(I35:K35,"P") -> 1 | AK25: =SUM(K12,I16,I24) -> 2 | AL25: =SUM(I12,K16,K24) -> 2 | AM25: =AK25-AL25 -> 0 | AN25: =(AH25*3)+AI25*vcp -> 4 | AO25: =IF($AO$6>0,AN25*10) -> 40 | AP25: =IF(AF25=$R$38,BF25-100,IF(AF25=$R$37,BF25-200,IF(AF25=$R$36,BF25-300,BF25))) -> -198 | AQ25: =IF(SUM($V$10:$V$29)>0,VLOOKUP(4,$AE$10:$AF$29,2,0),"") -> COREA del SUR | AR25: =N24&F24 -> MÉXICOREP. CHECA | AS25: =IF(I24>K24,F24,IF(K24>I24,N24,"")) -> MÉXICO | AT25: =K24 -> 1 | AU25: =I24 -> 0 | AV25: =AT25-AU25 -> 1 | AW25: =RANK(AY25,$AY$10:$AY$29,0) -> 2 | AX25: =IF(AND($AO$6>0,$AP$6>0),AN25*10000+AZ25,AO25) -> 40 | AY25: =IF(AND($AO$6>0,$AP$6>0),AN25*10000+AZ25-3,AO25) -> 40 | AZ25: =--IF(AND($AO$6>0,$AP$6>0), _xlfn.IFNA(IF(AN25=VLOOKUP(1,$AD$10:$AN$29,11,0),IF(VLOOKUP(AF25&VLOOKUP(1,$AD$10:$AN$29,3,0),$AR$8:$AS$29,2,0)=AF25,1000)),0)+ _xlfn.IFNA(IF(AN25=VLOOKUP(2,$AD$10:$AN$29,11,0),IF(VLOOKUP(AF25&VLOOKUP(2,$AD$10:$AN$29,3,0),$AR$8:$AS$29,2,0)=AF25,1000)),0)+ _xlfn.IFNA(IF(AN25=VLOOKUP(3,$AD$10:$AN$29,11,0),IF(VLOOKUP(AF25&VLOOKUP(3,$AD$10:$AN$29,3,0),$AR$8:$AS$29,2,0)=AF25,1000)),0)+ _xlfn.IFNA(IF(AN25=VLOOKUP(4,$AD$10:$AN$29,11,0),IF(VLOOKUP(AF25&VLOOKUP(4,$AD$10:$AN$29,3,0),$AR$8:$AS$29,2,0)=AF25,1000)),0)) -> 0 | BA25: =RANK(BB25,$BB$10:$BB$29,0) -> 2 | BB25: =AX25+BD25 -> 40 | BC25: =AX25+BD25 -> 40 | BD25: =--IF(AND($AO$6>0,$AX$6>0), _xlfn.IFNA(IF(AX25=VLOOKUP(1,$AW$10:$AX$29,2,0),IF(VLOOKUP(AF25&VLOOKUP(1,$AD$10:$AX$29,3,0),$AR$8:$AV$29,2,0)=AF25,VLOOKUP(AF25&VLOOKUP(1,$AD$10:$AX$29,3,0),$AR$8:$AV$29,5,0)*100+VLOOKUP(AF25&VLOOKUP(1,$AD$10:$AX$29,3,0),$AR$8:$AV$29,3,0)*10)),0)+ _xlfn.IFNA(IF(AX25=VLOOKUP(2,$AW$10:$AX$29,2,0),IF(VLOOKUP(AF25&VLOOKUP(2,$AD$10:$AX$29,3,0),$AR$8:$AV$29,2,0)=AF25,VLOOKUP(AF25&VLOOKUP(2,$AD$10:$AX$29,3,0),$AR$8:$AV$29,5,0)*100+VLOOKUP(AF25&VLOOKUP(2,$AD$10:$AX$29,3,0),$AR$8:$AV$29,3,0)*10)),0)+ _xlfn.IFNA(IF(AX25=VLOOKUP(3,$AW$10:$AX$29,2,0),IF(VLOOKUP(AF25&VLOOKUP(3,$AD$10:$AX$29,3,0),$AR$8:$AV$29,2,0)=AF25,VLOOKUP(AF25&VLOOKUP(3,$AD$10:$AX$29,3,0),$AR$8:$AV$29,5,0)*100+VLOOKUP(AF25&VLOOKUP(3,$AD$10:$AX$29,3,0),$AR$8:$AV$29,3,0)*10)),0)+ _xlfn.IFNA(IF(AX25=VLOOKUP(4,$AW$10:$AX$29,2,0),IF(VLOOKUP(AF25&VLOOKUP(4,$AD$10:$AX$29,3,0),$AR$8:$AV$29,2,0)=AF25,VLOOKUP(AF25&VLOOKUP(4,$AD$10:$AX$29,3,0),$AR$8:$AV$29,5,0)*100+VLOOKUP(AF25&VLOOKUP(4,$AD$10:$AX$29,3,0),$AR$8:$AV$29,3,0)*10)),0)) -> 0 | BE25: =IF(AND($AO$6>0,$BB$6>0),AN25*1000+AM25*100+AK25*10,0)/100+BB25 -> 40 | BF25: =RANK(BE25,$BE$10:$BE$29) -> 2 | BG25: =BE25 -> 40 | BH25: =COUNTIF($BG$10:$BG$29,BG25) -> 1
A28: 54 | B28: 54 | C28: =VLOOKUP(A28,tDatos[],IF(UTCElegido="",3,12),0) -> 46197 | D28: =VLOOKUP(A28,tDatos[],IF(UTCElegido="",4,12),0) -> 0.875 | F28: =VLOOKUP(A28,tDatos[],5,0) -> SUDÁFRICA | G28: =IF(OR(I28="",K28=""),"",IF(I28=K28,"E",IF(I28>K28,"G","P"))) -> G | I28: 2 | J28: - | K28: 0 | L28: =IF(OR(K28="",I28=""),"",IF(K28=I28,"E",IF(K28>I28,"G","P"))) -> P | N28: =VLOOKUP(A28,tDatos[],6,0) -> COREA del SUR | P28: =VLOOKUP(A28,tDatos[],9,0) -> Monterrey | AR28: =F28&N28 -> SUDÁFRICACOREA del SUR | AS28: =IF(I28>K28,F28,IF(K28>I28,N28,"")) -> SUDÁFRICA | AT28: =I28 -> 2 | AU28: =K28 -> 0 | AV28: =AT28-AU28 -> 2
AR29: =N28&F28 -> COREA del SURSUDÁFRICA | AS29: =IF(I28>K28,F28,IF(K28>I28,N28,"")) -> SUDÁFRICA | AT29: =K28 -> 0 | AU29: =I28 -> 2 | AV29: =AT29-AU29 -> -2
R31: =IF(AO6=12,IF(BH31>4,"***¡ES NECESARIO DESEMPATAR MANUALMENTE!***",""),"") | BH31: =SUM(BH10:BH29) -> 4
F32: =F8 -> MÉXICO | I32: =G8 -> G | J32: =G20 -> G | K32: =L24 -> G
F33: =N8 -> SUDÁFRICA | I33: =L8 -> P | J33: =L16 -> P | K33: =G28 -> G
F34: =F12 -> COREA del SUR | I34: =G12 -> E | J34: =L20 -> P | K34: =L28 -> P
F35: =N12 -> REP. CHECA | I35: =L12 -> E | J35: =G16 -> G | K35: =G24 -> P
N36: Las posiciones se resuelven de forma automática en casi todos los casos. | Q36: Primer puesto: | R36: MÉXICO
N37: Pero, de ser necesario, puedes determinar el orden manualmente: | Q37: Segundo puesto: | R37: REP. CHECA
Q38: Tercer puesto: | R38: SUDÁFRICA

Sheet B
B5: Los horarios de los partidos corresponden a la localidad donde se juega el encuentro.
B6: # | C6: Fechas | D6: Horas | E6: PARTIDOS | P6: Estadios | R6: POSICIONES | AO6: =COUNT(I8,K8,I12,K12,I16,K16,I20,K20,I24,K24,I28,K28) -> 12 | AP6: =(AN10=AN15)+(AN15=AN20)+(AN20=AN25)+(AN10=AN20)+(AN15=AN25)+(AN10=AN25) -> 0 | AR6: Partido | AS6: Ganador | AT6: 1 | AU6: 2 | AV6: Dif. | AX6: =(AX10=AX15)+(AX15=AX20)+(AX20=AX25)+(AX10=AX20)+(AX15=AX25)+(AX10=AX25) -> 0 | BB6: =(BB10=BB15)+(BB15=BB20)+(BB20=BB25)+(BB10=BB20)+(BB15=BB25)+(BB10=BB25) -> 0
AC7: Puntos
A8: 3 | B8: 3 | C8: =VLOOKUP(A8,tDatos[],IF(UTCElegido="",3,12),0) -> 46185 | D8: =VLOOKUP(A8,tDatos[],IF(UTCElegido="",4,12),0) -> 0.625 | F8: =VLOOKUP(A8,tDatos[],5,0) -> CANADÁ | G8: =IF(AND(I8<>"",K8<>""),IF(I8=K8,"E",IF(I8>K8,"G","P")),"") -> E | I8: 0 | J8: - | K8: 0 | L8: =IF(AND(K8<>"",I8<>""),IF(K8=I8,"E",IF(K8>I8,"G","P")),"") -> E | N8: =VLOOKUP(A8,tDatos[],6,0) -> BOSNIA y HERZEG. | P8: =VLOOKUP(A8,tDatos[],9,0) -> Toronto | V8: Jug. | W8: Gan. | X8: Emp. | Y8: Per. | Z8: GF | AA8: GC | AB8: DG | AG8: Jug. | AH8: Gan. | AI8: Emp. | AJ8: Per. | AK8: GF | AL8: GC | AM8: Dif. | AN8: Pts. | AR8: =F8&N8 -> CANADÁBOSNIA y HERZEG. | AS8: =IF(I8>K8,F8,IF(K8>I8,N8,"")) | AT8: =I8 -> 0 | AU8: =K8 -> 0 | AV8: =AT8-AU8 -> 0
AR9: =N8&F8 -> BOSNIA y HERZEG.CANADÁ | AS9: =IF(I8>K8,F8,IF(K8>I8,N8,"")) | AT9: =K8 -> 0 | AU9: =I8 -> 0 | AV9: =AT9-AU9 -> 0
R10: =" 1) " & VLOOKUP(1,$AE$10:$AF$29,2,0) -> 1) SUIZA | V10: =VLOOKUP(1,$AE$10:$AG$29,3,0) -> 3 | W10: =VLOOKUP(1,$AE$10:$AH$29,4,0) -> 3 | X10: =VLOOKUP(1,$AE$10:$AI$29,5,0) -> 0 | Y10: =VLOOKUP(1,$AE$10:$AJ$29,6,0) -> 0 | Z10: =VLOOKUP(1,$AE$10:$AK$29,7,0) -> 8 | AA10: =VLOOKUP(1,$AE$10:$AL$29,8,0) -> 0 | AB10: =Z10-AA10 -> 8 | AC10: =(W10*3)+X10 -> 9 | AD10: =RANK(AO10,$AO$10:$AO$29,0) -> 3 | AE10: =RANK(AP10,$AP$10:$AP$29,1) -> 3 | AF10: =F8 -> CANADÁ | AG10: =3-COUNTIF(I32:K32,"") -> 3 | AH10: =COUNTIF(I32:K32,"G") -> 0 | AI10: =COUNTIF(I32:K32,"E") -> 2 | AJ10: =COUNTIF(I32:K32,"P") -> 1 | AK10: =SUM(I8,I20,K24) -> 1 | AL10: =SUM(K8,K20,I24) -> 4 | AM10: =AK10-AL10 -> -3 | AN10: =(AH10*3)+AI10*vcp -> 2 | AO10: =IF($AO$6>0,AN10*10+3) -> 23 | AP10: =IF(AF10=$R$38,BF10-100,IF(AF10=$R$37,BF10-200,IF(AF10=$R$36,BF10-300,BF10))) -> -97 | AQ10: =IF(R36="",IF(SUM($V$10:$V$29)>0,VLOOKUP(1,$AE$10:$AF$29,2,0),""),R36) -> SUIZA | AW10: =RANK(AY10,$AY$10:$AY$29,0) -> 3 | AX10: =IF(AND($AO$6>0,$AP$6>0),AN10*10000+AZ10,AO10) -> 23 | AY10: =IF(AND($AO$6>0,$AP$6>0),AN10*10000+AZ10,AO10) -> 23 | AZ10: =--IF(AND($AO$6>0,$AP$6>0), _xlfn.IFNA(IF(AN10=VLOOKUP(1,$AD$10:$AN$29,11,0),IF(VLOOKUP(AF10&VLOOKUP(1,$AD$10:$AN$29,3,0),$AR$8:$AS$29,2,0)=AF10,1000)),0)+ _xlfn.IFNA(IF(AN10=VLOOKUP(2,$AD$10:$AN$29,11,0),IF(VLOOKUP(AF10&VLOOKUP(2,$AD$10:$AN$29,3,0),$AR$8:$AS$29,2,0)=AF10,1000)),0)+ _xlfn.IFNA(IF(AN10=VLOOKUP(3,$AD$10:$AN$29,11,0),IF(VLOOKUP(AF10&VLOOKUP(3,$AD$10:$AN$29,3,0),$AR$8:$AS$29,2,0)=AF10,1000)),0)+ _xlfn.IFNA(IF(AN10=VLOOKUP(4,$AD$10:$AN$29,11,0),IF(VLOOKUP(AF10&VLOOKUP(4,$AD$10:$AN$29,3,0),$AR$8:$AS$29,2,0)=AF10,1000)),0)) -> 0 | BA10: =RANK(BB10,$BB$10:$BB$29,0) -> 3 | BB10: =AX10+BD10 -> 23 | BC10: =AX10+BD10+3 -> 26 | BD10: =--IF(AND($AO$6>0,$AX$6>0), _xlfn.IFNA(IF(AX10=VLOOKUP(1,$AW$10:$AX$29,2,0),IF(VLOOKUP(AF10&VLOOKUP(1,$AD$10:$AX$29,3,0),$AR$8:$AV$29,2,0)=AF10,VLOOKUP(AF10&VLOOKUP(1,$AD$10:$AX$29,3,0),$AR$8:$AV$29,5,0)*100+VLOOKUP(AF10&VLOOKUP(1,$AD$10:$AX$29,3,0),$AR$8:$AV$29,3,0)*10)),0)+ _xlfn.IFNA(IF(AX10=VLOOKUP(2,$AW$10:$AX$29,2,0),IF(VLOOKUP(AF10&VLOOKUP(2,$AD$10:$AX$29,3,0),$AR$8:$AV$29,2,0)=AF10,VLOOKUP(AF10&VLOOKUP(2,$AD$10:$AX$29,3,0),$AR$8:$AV$29,5,0)*100+VLOOKUP(AF10&VLOOKUP(2,$AD$10:$AX$29,3,0),$AR$8:$AV$29,3,0)*10)),0)+ _xlfn.IFNA(IF(AX10=VLOOKUP(3,$AW$10:$AX$29,2,0),IF(VLOOKUP(AF10&VLOOKUP(3,$AD$10:$AX$29,3,0),$AR$8:$AV$29,2,0)=AF10,VLOOKUP(AF10&VLOOKUP(3,$AD$10:$AX$29,3,0),$AR$8:$AV$29,5,0)*100+VLOOKUP(AF10&VLOOKUP(3,$AD$10:$AX$29,3,0),$AR$8:$AV$29,3,0)*10)),0)+ _xlfn.IFNA(IF(AX10=VLOOKUP(4,$AW$10:$AX$29,2,0),IF(VLOOKUP(AF10&VLOOKUP(4,$AD$10:$AX$29,3,0),$AR$8:$AV$29,2,0)=AF10,VLOOKUP(AF10&VLOOKUP(4,$AD$10:$AX$29,3,0),$AR$8:$AV$29,5,0)*100+VLOOKUP(AF10&VLOOKUP(4,$AD$10:$AX$29,3,0),$AR$8:$AV$29,3,0)*10)),0)) -> 0 | BE10: =(IF(AND($AO$6>0,$BB$6>0),AN10*1000+AM10*100+AK10*10,0)+3)/100+BB10 -> 23.03 | BF10: =RANK(BE10,$BE$10:$BE$29) -> 3 | BG10: =BE10-0.03 -> 23 | BH10: =COUNTIF($BG$10:$BG$29,BG10) -> 1
A12: 5 | B12: 8 | C12: =VLOOKUP(A12,tDatos[],IF(UTCElegido="",3,12),0) -> 46186 | D12: =VLOOKUP(A12,tDatos[],IF(UTCElegido="",4,12),0) -> 0.625 | F12: =VLOOKUP(A12,tDatos[],5,0) -> CATAR | G12: =IF(AND(I12<>"",K12<>""),IF(I12=K12,"E",IF(I12>K12,"G","P")),"") -> P | I12: 0 | J12: - | K12: 3 | L12: =IF(AND(K12<>"",I12<>""),IF(K12=I12,"E",IF(K12>I12,"G","P")),"") -> G | N12: =VLOOKUP(A12,tDatos[],6,0) -> SUIZA | P12: =VLOOKUP(A12,tDatos[],9,0) -> San Francisco | AR12: =F12&N12 -> CATARSUIZA | AS12: =IF(I12>K12,F12,IF(K12>I12,N12,"")) -> SUIZA | AT12: =I12 -> 0 | AU12: =K12 -> 3 | AV12: =AT12-AU12 -> -3
AR13: =N12&F12 -> SUIZACATAR | AS13: =IF(I12>K12,F12,IF(K12>I12,N12,"")) -> SUIZA | AT13: =K12 -> 3 | AU13: =I12 -> 0 | AV13: =AT13-AU13 -> 3
R15: =" 2) " & VLOOKUP(2,$AE$10:$AF$29,2,0) -> 2) CATAR | V15: =VLOOKUP(2,$AE$10:$AG$29,3,0) -> 3 | W15: =VLOOKUP(2,$AE$10:$AH$29,4,0) -> 1 | X15: =VLOOKUP(2,$AE$10:$AI$29,5,0) -> 1 | Y15: =VLOOKUP(2,$AE$10:$AJ$29,6,0) -> 1 | Z15: =VLOOKUP(2,$AE$10:$AK$29,7,0) -> 2 | AA15: =VLOOKUP(2,$AE$10:$AL$29,8,0) -> 4 | AB15: =Z15-AA15 -> -2 | AC15: =(W15*3)+X15 -> 4 | AD15: =RANK(AO15,$AO$10:$AO$29,0) -> 4 | AE15: =RANK(AP15,$AP$10:$AP$29,1) -> 4 | AF15: =N8 -> BOSNIA y HERZEG. | AG15: =3-COUNTIF(I33:K33,"") -> 3 | AH15: =COUNTIF(I33:K33,"G") -> 0 | AI15: =COUNTIF(I33:K33,"E") -> 1 | AJ15: =COUNTIF(I33:K33,"P") -> 2 | AK15: =SUM(K8,K16,I28) -> 0 | AL15: =SUM(I8,I16,K28) -> 3 | AM15: =AK15-AL15 -> -3 | AN15: =(AH15*3)+AI15*vcp -> 1 | AO15: =IF($AO$6>0,AN15*10+2) -> 12 | AP15: =IF(AF15=$R$38,BF15-100,IF(AF15=$R$37,BF15-200,IF(AF15=$R$36,BF15-300,BF15))) -> 4 | AQ15: =IF(R37="",IF(SUM($V$10:$V$29)>0,VLOOKUP(2,$AE$10:$AF$29,2,0),""),R37) -> CATAR | AW15: =RANK(AY15,$AY$10:$AY$29,0) -> 4 | AX15: =IF(AND($AO$6>0,$AP$6>0),AN15*10000+AZ15,AO15) -> 12 | AY15: =IF(AND($AO$6>0,$AP$6>0),AN15*10000+AZ15-1,AO15) -> 12 | AZ15: =--IF(AND($AO$6>0,$AP$6>0), _xlfn.IFNA(IF(AN15=VLOOKUP(1,$AD$10:$AN$29,11,0),IF(VLOOKUP(AF15&VLOOKUP(1,$AD$10:$AN$29,3,0),$AR$8:$AS$29,2,0)=AF15,1000)),0)+ _xlfn.IFNA(IF(AN15=VLOOKUP(2,$AD$10:$AN$29,11,0),IF(VLOOKUP(AF15&VLOOKUP(2,$AD$10:$AN$29,3,0),$AR$8:$AS$29,2,0)=AF15,1000)),0)+ _xlfn.IFNA(IF(AN15=VLOOKUP(3,$AD$10:$AN$29,11,0),IF(VLOOKUP(AF15&VLOOKUP(3,$AD$10:$AN$29,3,0),$AR$8:$AS$29,2,0)=AF15,1000)),0)+ _xlfn.IFNA(IF(AN15=VLOOKUP(4,$AD$10:$AN$29,11,0),IF(VLOOKUP(AF15&VLOOKUP(4,$AD$10:$AN$29,3,0),$AR$8:$AS$29,2,0)=AF15,1000)),0)) -> 0 | BA15: =RANK(BB15,$BB$10:$BB$29,0) -> 4 | BB15: =AX15+BD15 -> 12 | BC15: =AX15+BD15+2 -> 14 | BD15: =--IF(AND($AO$6>0,$AX$6>0), _xlfn.IFNA(IF(AX15=VLOOKUP(1,$AW$10:$AX$29,2,0),IF(VLOOKUP(AF15&VLOOKUP(1,$AD$10:$AX$29,3,0),$AR$8:$AV$29,2,0)=AF15,VLOOKUP(AF15&VLOOKUP(1,$AD$10:$AX$29,3,0),$AR$8:$AV$29,5,0)*100+VLOOKUP(AF15&VLOOKUP(1,$AD$10:$AX$29,3,0),$AR$8:$AV$29,3,0)*10)),0)+ _xlfn.IFNA(IF(AX15=VLOOKUP(2,$AW$10:$AX$29,2,0),IF(VLOOKUP(AF15&VLOOKUP(2,$AD$10:$AX$29,3,0),$AR$8:$AV$29,2,0)=AF15,VLOOKUP(AF15&VLOOKUP(2,$AD$10:$AX$29,3,0),$AR$8:$AV$29,5,0)*100+VLOOKUP(AF15&VLOOKUP(2,$AD$10:$AX$29,3,0),$AR$8:$AV$29,3,0)*10)),0)+ _xlfn.IFNA(IF(AX15=VLOOKUP(3,$AW$10:$AX$29,2,0),IF(VLOOKUP(AF15&VLOOKUP(3,$AD$10:$AX$29,3,0),$AR$8:$AV$29,2,0)=AF15,VLOOKUP(AF15&VLOOKUP(3,$AD$10:$AX$29,3,0),$AR$8:$AV$29,5,0)*100+VLOOKUP(AF15&VLOOKUP(3,$AD$10:$AX$29,3,0),$AR$8:$AV$29,3,0)*10)),0)+ _xlfn.IFNA(IF(AX15=VLOOKUP(4,$AW$10:$AX$29,2,0),IF(VLOOKUP(AF15&VLOOKUP(4,$AD$10:$AX$29,3,0),$AR$8:$AV$29,2,0)=AF15,VLOOKUP(AF15&VLOOKUP(4,$AD$10:$AX$29,3,0),$AR$8:$AV$29,5,0)*100+VLOOKUP(AF15&VLOOKUP(4,$AD$10:$AX$29,3,0),$AR$8:$AV$29,3,0)*10)),0)) -> 0 | BE15: =(IF(AND($AO$6>0,$BB$6>0),AN15*1000+AM15*100+AK15*10,0)+2)/100+BB15 -> 12.02 | BF15: =RANK(BE15,$BE$10:$BE$29) -> 4 | BG15: =BE15-0.02 -> 12 | BH15: =COUNTIF($BG$10:$BG$29,BG15) -> 1
A16: 26 | B16: 26 | C16: =VLOOKUP(A16,tDatos[],IF(UTCElegido="",3,12),0) -> 46191 | D16: =VLOOKUP(A16,tDatos[],IF(UTCElegido="",4,12),0) -> 0.625 | F16: =VLOOKUP(A16,tDatos[],5,0) -> SUIZA | G16: =IF(AND(I16<>"",K16<>""),IF(I16=K16,"E",IF(I16>K16,"G","P")),"") -> G | I16: 2 | J16: - | K16: 0 | L16: =IF(AND(K16<>"",I16<>""),IF(K16=I16,"E",IF(K16>I16,"G","P")),"") -> P | N16: =VLOOKUP(A16,tDatos[],6,0) -> BOSNIA y HERZEG. | P16: =VLOOKUP(A16,tDatos[],9,0) -> Los Angeles | AR16: =F16&N16 -> SUIZABOSNIA y HERZEG. | AS16: =IF(I16>K16,F16,IF(K16>I16,N16,"")) -> SUIZA | AT16: =I16 -> 2 | AU16: =K16 -> 0 | AV16: =AT16-AU16 -> 2
AR17: =N16&F16 -> BOSNIA y HERZEG.SUIZA | AS17: =IF(I16>K16,F16,IF(K16>I16,N16,"")) -> SUIZA | AT17: =K16 -> 0 | AU17: =I16 -> 2 | AV17: =AT17-AU17 -> -2
A20: 27 | B20: 27 | C20: =VLOOKUP(A20,tDatos[],IF(UTCElegido="",3,12),0) -> 46191 | D20: =VLOOKUP(A20,tDatos[],IF(UTCElegido="",4,12),0) -> 0.75 | F20: =VLOOKUP(A20,tDatos[],5,0) -> CANADÁ | G20: =IF(AND(I20<>"",K20<>""),IF(I20=K20,"E",IF(I20>K20,"G","P")),"") -> E | I20: 1 | J20: - | K20: 1 | L20: =IF(AND(K20<>"",I20<>""),IF(K20=I20,"E",IF(K20>I20,"G","P")),"") -> E | N20: =VLOOKUP(A20,tDatos[],6,0) -> CATAR | P20: =VLOOKUP(A20,tDatos[],9,0) -> Vancouver | R20: =" 3) " & VLOOKUP(3,$AE$10:$AF$29,2,0) -> 3) CANADÁ | V20: =VLOOKUP(3,$AE$10:$AG$29,3,0) -> 3 | W20: =VLOOKUP(3,$AE$10:$AH$29,4,0) -> 0 | X20: =VLOOKUP(3,$AE$10:$AI$29,5,0) -> 2 | Y20: =VLOOKUP(3,$AE$10:$AJ$29,6,0) -> 1 | Z20: =VLOOKUP(3,$AE$10:$AK$29,7,0) -> 1 | AA20: =VLOOKUP(3,$AE$10:$AL$29,8,0) -> 4 | AB20: =Z20-AA20 -> -3 | AC20: =(W20*3)+X20 -> 2 | AD20: =RANK(AO20,$AO$10:$AO$29,0) -> 2 | AE20: =RANK(AP20,$AP$10:$AP$29,1) -> 2 | AF20: =F12 -> CATAR | AG20: =3-COUNTIF(I34:K34,"") -> 3 | AH20: =COUNTIF(I34:K34,"G") -> 1 | AI20: =COUNTIF(I34:K34,"E") -> 1 | AJ20: =COUNTIF(I34:K34,"P") -> 1 | AK20: =SUM(I12,K20,K28) -> 2 | AL20: =SUM(K12,I20,I28) -> 4 | AM20: =AK20-AL20 -> -2 | AN20: =(AH20*3)+AI20*vcp -> 4 | AO20: =IF($AO$6>0,AN20*10+1) -> 41 | AP20: =IF(AF20=$R$38,BF20-100,IF(AF20=$R$37,BF20-200,IF(AF20=$R$36,BF20-300,BF20))) -> -198 | AQ20: =IF(R38="",IF(SUM($V$10:$V$29)>0,VLOOKUP(3,$AE$10:$AF$29,2,0),""),R38) -> CANADÁ | AR20: =F20&N20 -> CANADÁCATAR | AS20: =IF(I20>K20,F20,IF(K20>I20,N20,"")) | AT20: =I20 -> 1 | AU20: =K20 -> 1 | AV20: =AT20-AU20 -> 0 | AW20: =RANK(AY20,$AY$10:$AY$29,0) -> 2 | AX20: =IF(AND($AO$6>0,$AP$6>0),AN20*10000+AZ20,AO20) -> 41 | AY20: =IF(AND($AO$6>0,$AP$6>0),AN20*10000+AZ20-2,AO20) -> 41 | AZ20: =--IF(AND($AO$6>0,$AP$6>0), _xlfn.IFNA(IF(AN20=VLOOKUP(1,$AD$10:$AN$29,11,0),IF(VLOOKUP(AF20&VLOOKUP(1,$AD$10:$AN$29,3,0),$AR$8:$AS$29,2,0)=AF20,1000)),0)+ _xlfn.IFNA(IF(AN20=VLOOKUP(2,$AD$10:$AN$29,11,0),IF(VLOOKUP(AF20&VLOOKUP(2,$AD$10:$AN$29,3,0),$AR$8:$AS$29,2,0)=AF20,1000)),0)+ _xlfn.IFNA(IF(AN20=VLOOKUP(3,$AD$10:$AN$29,11,0),IF(VLOOKUP(AF20&VLOOKUP(3,$AD$10:$AN$29,3,0),$AR$8:$AS$29,2,0)=AF20,1000)),0)+ _xlfn.IFNA(IF(AN20=VLOOKUP(4,$AD$10:$AN$29,11,0),IF(VLOOKUP(AF20&VLOOKUP(4,$AD$10:$AN$29,3,0),$AR$8:$AS$29,2,0)=AF20,1000)),0)) -> 0 | BA20: =RANK(BB20,$BB$10:$BB$29,0) -> 2 | BB20: =AX20+BD20 -> 41 | BC20: =AX20+BD20+1 -> 42 | BD20: =--IF(AND($AO$6>0,$AX$6>0), _xlfn.IFNA(IF(AX20=VLOOKUP(1,$AW$10:$AX$29,2,0),IF(VLOOKUP(AF20&VLOOKUP(1,$AD$10:$AX$29,3,0),$AR$8:$AV$29,2,0)=AF20,VLOOKUP(AF20&VLOOKUP(1,$AD$10:$AX$29,3,0),$AR$8:$AV$29,5,0)*100+VLOOKUP(AF20&VLOOKUP(1,$AD$10:$AX$29,3,0),$AR$8:$AV$29,3,0)*10)),0)+ _xlfn.IFNA(IF(AX20=VLOOKUP(2,$AW$10:$AX$29,2,0),IF(VLOOKUP(AF20&VLOOKUP(2,$AD$10:$AX$29,3,0),$AR$8:$AV$29,2,0)=AF20,VLOOKUP(AF20&VLOOKUP(2,$AD$10:$AX$29,3,0),$AR$8:$AV$29,5,0)*100+VLOOKUP(AF20&VLOOKUP(2,$AD$10:$AX$29,3,0),$AR$8:$AV$29,3,0)*10)),0)+ _xlfn.IFNA(IF(AX20=VLOOKUP(3,$AW$10:$AX$29,2,0),IF(VLOOKUP(AF20&VLOOKUP(3,$AD$10:$AX$29,3,0),$AR$8:$AV$29,2,0)=AF20,VLOOKUP(AF20&VLOOKUP(3,$AD$10:$AX$29,3,0),$AR$8:$AV$29,5,0)*100+VLOOKUP(AF20&VLOOKUP(3,$AD$10:$AX$29,3,0),$AR$8:$AV$29,3,0)*10)),0)+ _xlfn.IFNA(IF(AX20=VLOOKUP(4,$AW$10:$AX$29,2,0),IF(VLOOKUP(AF20&VLOOKUP(4,$AD$10:$AX$29,3,0),$AR$8:$AV$29,2,0)=AF20,VLOOKUP(AF20&VLOOKUP(4,$AD$10:$AX$29,3,0),$AR$8:$AV$29,5,0)*100+VLOOKUP(AF20&VLOOKUP(4,$AD$10:$AX$29,3,0),$AR$8:$AV$29,3,0)*10)),0)) -> 0 | BE20: =(IF(AND($AO$6>0,$BB$6>0),AN20*1000+AM20*100+AK20*10,0)+1)/100+BB20 -> 41.01 | BF20: =RANK(BE20,$BE$10:$BE$29) -> 2 | BG20: =BE20-0.01 -> 41 | BH20: =COUNTIF($BG$10:$BG$29,BG20) -> 1
AR21: =N20&F20 -> CATARCANADÁ | AS21: =IF(I20>K20,F20,IF(K20>I20,N20,"")) | AT21: =K20 -> 1 | AU21: =I20 -> 1 | AV21: =AT21-AU21 -> 0
A24: 49 | B24: 51 | C24: =VLOOKUP(A24,tDatos[],IF(UTCElegido="",3,12),0) -> 46197 | D24: =VLOOKUP(A24,tDatos[],IF(UTCElegido="",4,12),0) -> 0.625 | F24: =VLOOKUP(A24,tDatos[],5,0) -> SUIZA | G24: =IF(AND(I24<>"",K24<>""),IF(I24=K24,"E",IF(I24>K24,"G","P")),"") -> G | I24: 3 | J24: - | K24: 0 | L24: =IF(AND(K24<>"",I24<>""),IF(K24=I24,"E",IF(K24>I24,"G","P")),"") -> P | N24: =VLOOKUP(A24,tDatos[],6,0) -> CANADÁ | P24: =VLOOKUP(A24,tDatos[],9,0) -> Vancouver | AR24: =F24&N24 -> SUIZACANADÁ | AS24: =IF(I24>K24,F24,IF(K24>I24,N24,"")) -> SUIZA | AT24: =I24 -> 3 | AU24: =K24 -> 0 | AV24: =AT24-AU24 -> 3
R25: =" 4) " & VLOOKUP(4,$AE$10:$AF$29,2,0) -> 4) BOSNIA y HERZEG. | V25: =VLOOKUP(4,$AE$10:$AG$29,3,0) -> 3 | W25: =VLOOKUP(4,$AE$10:$AH$29,4,0) -> 0 | X25: =VLOOKUP(4,$AE$10:$AI$29,5,0) -> 1 | Y25: =VLOOKUP(4,$AE$10:$AJ$29,6,0) -> 2 | Z25: =VLOOKUP(4,$AE$10:$AK$29,7,0) -> 0 | AA25: =VLOOKUP(4,$AE$10:$AL$29,8,0) -> 3 | AB25: =Z25-AA25 -> -3 | AC25: =(W25*3)+X25 -> 1 | AD25: =RANK(AO25,$AO$10:$AO$29,0) -> 1 | AE25: =RANK(AP25,$AP$10:$AP$29,1) -> 1 | AF25: =N12 -> SUIZA | AG25: =3-COUNTIF(I35:K35,"") -> 3 | AH25: =COUNTIF(I35:K35,"G") -> 3 | AI25: =COUNTIF(I35:K35,"E") -> 0 | AJ25: =COUNTIF(I35:K35,"P") -> 0 | AK25: =SUM(K12,I16,I24) -> 8 | AL25: =SUM(I12,K16,K24) -> 0 | AM25: =AK25-AL25 -> 8 | AN25: =(AH25*3)+AI25*vcp -> 9 | AO25: =IF($AO$6>0,AN25*10) -> 90 | AP25: =IF(AF25=$R$38,BF25-100,IF(AF25=$R$37,BF25-200,IF(AF25=$R$36,BF25-300,BF25))) -> -299 | AQ25: =IF(SUM($V$10:$V$29)>0,VLOOKUP(4,$AE$10:$AF$29,2,0),"") -> BOSNIA y HERZEG. | AR25: =N24&F24 -> CANADÁSUIZA | AS25: =IF(I24>K24,F24,IF(K24>I24,N24,"")) -> SUIZA | AT25: =K24 -> 0 | AU25: =I24 -> 3 | AV25: =AT25-AU25 -> -3 | AW25: =RANK(AY25,$AY$10:$AY$29,0) -> 1 | AX25: =IF(AND($AO$6>0,$AP$6>0),AN25*10000+AZ25,AO25) -> 90 | AY25: =IF(AND($AO$6>0,$AP$6>0),AN25*10000+AZ25-3,AO25) -> 90 | AZ25: =--IF(AND($AO$6>0,$AP$6>0), _xlfn.IFNA(IF(AN25=VLOOKUP(1,$AD$10:$AN$29,11,0),IF(VLOOKUP(AF25&VLOOKUP(1,$AD$10:$AN$29,3,0),$AR$8:$AS$29,2,0)=AF25,1000)),0)+ _xlfn.IFNA(IF(AN25=VLOOKUP(2,$AD$10:$AN$29,11,0),IF(VLOOKUP(AF25&VLOOKUP(2,$AD$10:$AN$29,3,0),$AR$8:$AS$29,2,0)=AF25,1000)),0)+ _xlfn.IFNA(IF(AN25=VLOOKUP(3,$AD$10:$AN$29,11,0),IF(VLOOKUP(AF25&VLOOKUP(3,$AD$10:$AN$29,3,0),$AR$8:$AS$29,2,0)=AF25,1000)),0)+ _xlfn.IFNA(IF(AN25=VLOOKUP(4,$AD$10:$AN$29,11,0),IF(VLOOKUP(AF25&VLOOKUP(4,$AD$10:$AN$29,3,0),$AR$8:$AS$29,2,0)=AF25,1000)),0)) -> 0 | BA25: =RANK(BB25,$BB$10:$BB$29,0) -> 1 | BB25: =AX25+BD25 -> 90 | BC25: =AX25+BD25 -> 90 | BD25: =--IF(AND($AO$6>0,$AX$6>0), _xlfn.IFNA(IF(AX25=VLOOKUP(1,$AW$10:$AX$29,2,0),IF(VLOOKUP(AF25&VLOOKUP(1,$AD$10:$AX$29,3,0),$AR$8:$AV$29,2,0)=AF25,VLOOKUP(AF25&VLOOKUP(1,$AD$10:$AX$29,3,0),$AR$8:$AV$29,5,0)*100+VLOOKUP(AF25&VLOOKUP(1,$AD$10:$AX$29,3,0),$AR$8:$AV$29,3,0)*10)),0)+ _xlfn.IFNA(IF(AX25=VLOOKUP(2,$AW$10:$AX$29,2,0),IF(VLOOKUP(AF25&VLOOKUP(2,$AD$10:$AX$29,3,0),$AR$8:$AV$29,2,0)=AF25,VLOOKUP(AF25&VLOOKUP(2,$AD$10:$AX$29,3,0),$AR$8:$AV$29,5,0)*100+VLOOKUP(AF25&VLOOKUP(2,$AD$10:$AX$29,3,0),$AR$8:$AV$29,3,0)*10)),0)+ _xlfn.IFNA(IF(AX25=VLOOKUP(3,$AW$10:$AX$29,2,0),IF(VLOOKUP(AF25&VLOOKUP(3,$AD$10:$AX$29,3,0),$AR$8:$AV$29,2,0)=AF25,VLOOKUP(AF25&VLOOKUP(3,$AD$10:$AX$29,3,0),$AR$8:$AV$29,5,0)*100+VLOOKUP(AF25&VLOOKUP(3,$AD$10:$AX$29,3,0),$AR$8:$AV$29,3,0)*10)),0)+ _xlfn.IFNA(IF(AX25=VLOOKUP(4,$AW$10:$AX$29,2,0),IF(VLOOKUP(AF25&VLOOKUP(4,$AD$10:$AX$29,3,0),$AR$8:$AV$29,2,0)=AF25,VLOOKUP(AF25&VLOOKUP(4,$AD$10:$AX$29,3,0),$AR$8:$AV$29,5,0)*100+VLOOKUP(AF25&VLOOKUP(4,$AD$10:$AX$29,3,0),$AR$8:$AV$29,3,0)*10)),0)) -> 0 | BE25: =IF(AND($AO$6>0,$BB$6>0),AN25*1000+AM25*100+AK25*10,0)/100+BB25 -> 90 | BF25: =RANK(BE25,$BE$10:$BE$29) -> 1 | BG25: =BE25 -> 90 | BH25: =COUNTIF($BG$10:$BG$29,BG25) -> 1
A28: 50 | B28: 52 | C28: =VLOOKUP(A28,tDatos[],IF(UTCElegido="",3,12),0) -> 46197 | D28: =VLOOKUP(A28,tDatos[],IF(UTCElegido="",4,12),0) -> 0.625 | F28: =VLOOKUP(A28,tDatos[],5,0) -> BOSNIA y HERZEG. | G28: =IF(AND(I28<>"",K28<>""),IF(I28=K28,"E",IF(I28>K28,"G","P")),"") -> P | I28: 0 | J28: - | K28: 1 | L28: =IF(AND(K28<>"",I28<>""),IF(K28=I28,"E",IF(K28>I28,"G","P")),"") -> G | N28: =VLOOKUP(A28,tDatos[],6,0) -> CATAR | P28: =VLOOKUP(A28,tDatos[],9,0) -> Seattle | AR28: =F28&N28 -> BOSNIA y HERZEG.CATAR | AS28: =IF(I28>K28,F28,IF(K28>I28,N28,"")) -> CATAR | AT28: =I28 -> 0 | AU28: =K28 -> 1 | AV28: =AT28-AU28 -> -1
AR29: =N28&F28 -> CATARBOSNIA y HERZEG. | AS29: =IF(I28>K28,F28,IF(K28>I28,N28,"")) -> CATAR | AT29: =K28 -> 1 | AU29: =I28 -> 0 | AV29: =AT29-AU29 -> 1
R31: =IF(AO6=12,IF(BH31>4,"***¡ES NECESARIO DESEMPATAR MANUALMENTE!***",""),"") | BH31: =SUM(BH10:BH29) -> 4
F32: =F8 -> CANADÁ | I32: =G8 -> E | J32: =G20 -> E | K32: =L24 -> P
F33: =N8 -> BOSNIA y HERZEG. | I33: =L8 -> E | J33: =L16 -> P | K33: =G28 -> P
F34: =F12 -> CATAR | I34: =G12 -> P | J34: =L20 -> E | K34: =L28 -> G
F35: =N12 -> SUIZA | I35: =L12 -> G | J35: =G16 -> G | K35: =G24 -> G
N36: Las posiciones se resuelven de forma automática en casi todos los casos. | Q36: Primer puesto: | R36: SUIZA
N37: Pero, de ser necesario, puedes determinar el orden manualmente: | Q37: Segundo puesto: | R37: CATAR
Q38: Tercer puesto: | R38: CANADÁ

Sheet C
B5: Los horarios de los partidos corresponden a la localidad donde se juega el encuentro.
B6: # | C6: Fechas | D6: Horas | E6: PARTIDOS | P6: Estadios | R6: POSICIONES | AO6: =COUNT(I8,K8,I12,K12,I16,K16,I20,K20,I24,K24,I28,K28) -> 12 | AP6: =(AN10=AN15)+(AN15=AN20)+(AN20=AN25)+(AN10=AN20)+(AN15=AN25)+(AN10=AN25) -> 1 | AR6: Partido | AS6: Ganador | AT6: 1 | AU6: 2 | AV6: Dif. | AX6: =(AX10=AX15)+(AX15=AX20)+(AX20=AX25)+(AX10=AX20)+(AX15=AX25)+(AX10=AX25) -> 1 | BB6: =(BB10=BB15)+(BB15=BB20)+(BB20=BB25)+(BB10=BB20)+(BB15=BB25)+(BB10=BB25) -> 1
AC7: Puntos
A8: 6 | B8: 7 | C8: =VLOOKUP(A8,tDatos[],IF(UTCElegido="",3,12),0) -> 46186 | D8: =VLOOKUP(A8,tDatos[],IF(UTCElegido="",4,12),0) -> 0.75 | F8: =VLOOKUP(A8,tDatos[],5,0) -> BRASIL | G8: =IF(AND(I8<>"",K8<>""),IF(I8=K8,"E",IF(I8>K8,"G","P")),"") -> E | I8: 1 | J8: - | K8: 1 | L8: =IF(AND(K8<>"",I8<>""),IF(K8=I8,"E",IF(K8>I8,"G","P")),"") -> E | N8: =VLOOKUP(A8,tDatos[],6,0) -> MARRUECOS | P8: =VLOOKUP(A8,tDatos[],9,0) -> N. York/N. Jersey | V8: Jug. | W8: Gan. | X8: Emp. | Y8: Per. | Z8: GF | AA8: GC | AB8: DG | AG8: Jug. | AH8: Gan. | AI8: Emp. | AJ8: Per. | AK8: GF | AL8: GC | AM8: Dif. | AN8: Pts. | AR8: =F8&N8 -> BRASILMARRUECOS | AS8: =IF(I8>K8,F8,IF(K8>I8,N8,"")) | AT8: =I8 -> 1 | AU8: =K8 -> 1 | AV8: =AT8-AU8 -> 0
AR9: =N8&F8 -> MARRUECOSBRASIL | AS9: =IF(I8>K8,F8,IF(K8>I8,N8,"")) | AT9: =K8 -> 1 | AU9: =I8 -> 1 | AV9: =AT9-AU9 -> 0
R10: =" 1) " & VLOOKUP(1,$AE$10:$AF$29,2,0) -> 1) BRASIL | V10: =VLOOKUP(1,$AE$10:$AG$29,3,0) -> 3 | W10: =VLOOKUP(1,$AE$10:$AH$29,4,0) -> 2 | X10: =VLOOKUP(1,$AE$10:$AI$29,5,0) -> 1 | Y10: =VLOOKUP(1,$AE$10:$AJ$29,6,0) -> 0 | Z10: =VLOOKUP(1,$AE$10:$AK$29,7,0) -> 10 | AA10: =VLOOKUP(1,$AE$10:$AL$29,8,0) -> 2 | AB10: =Z10-AA10 -> 8 | AC10: =(W10*3)+X10 -> 7 | AD10: =RANK(AO10,$AO$10:$AO$29,0) -> 1 | AE10: =RANK(AP10,$AP$10:$AP$29,1) -> 1 | AF10: =F8 -> BRASIL | AG10: =3-COUNTIF(I32:K32,"") -> 3 | AH10: =COUNTIF(I32:K32,"G") -> 2 | AI10: =COUNTIF(I32:K32,"E") -> 1 | AJ10: =COUNTIF(I32:K32,"P") -> 0 | AK10: =SUM(I8,I20,K24) -> 10 | AL10: =SUM(K8,K20,I24) -> 2 | AM10: =AK10-AL10 -> 8 | AN10: =(AH10*3)+AI10*vcp -> 7 | AO10: =IF($AO$6>0,AN10*10+3) -> 73 | AP10: =IF(AF10=$R$38,BF10-100,IF(AF10=$R$37,BF10-200,IF(AF10=$R$36,BF10-300,BF10))) -> -299 | AQ10: =IF(R36="",IF(SUM($V$10:$V$29)>0,VLOOKUP(1,$AE$10:$AF$29,2,0),""),R36) -> BRASIL | AW10: =RANK(AY10,$AY$10:$AY$29,0) -> 1 | AX10: =IF(AND($AO$6>0,$AP$6>0),AN10*10000+AZ10,AO10) -> 70000 | AY10: =IF(AND($AO$6>0,$AP$6>0),AN10*10000+AZ10,AO10) -> 70000 | AZ10: =--IF(AND($AO$6>0,$AP$6>0), _xlfn.IFNA(IF(AN10=VLOOKUP(1,$AD$10:$AN$29,11,0),IF(VLOOKUP(AF10&VLOOKUP(1,$AD$10:$AN$29,3,0),$AR$8:$AS$29,2,0)=AF10,1000)),0)+ _xlfn.IFNA(IF(AN10=VLOOKUP(2,$AD$10:$AN$29,11,0),IF(VLOOKUP(AF10&VLOOKUP(2,$AD$10:$AN$29,3,0),$AR$8:$AS$29,2,0)=AF10,1000)),0)+ _xlfn.IFNA(IF(AN10=VLOOKUP(3,$AD$10:$AN$29,11,0),IF(VLOOKUP(AF10&VLOOKUP(3,$AD$10:$AN$29,3,0),$AR$8:$AS$29,2,0)=AF10,1000)),0)+ _xlfn.IFNA(IF(AN10=VLOOKUP(4,$AD$10:$AN$29,11,0),IF(VLOOKUP(AF10&VLOOKUP(4,$AD$10:$AN$29,3,0),$AR$8:$AS$29,2,0)=AF10,1000)),0)) -> 0 | BA10: =RANK(BB10,$BB$10:$BB$29,0) -> 1 | BB10: =AX10+BD10 -> 70000 | BC10: =AX10+BD10+3 -> 70003 | BD10: =--IF(AND($AO$6>0,$AX$6>0), _xlfn.IFNA(IF(AX10=VLOOKUP(1,$AW$10:$AX$29,2,0),IF(VLOOKUP(AF10&VLOOKUP(1,$AD$10:$AX$29,3,0),$AR$8:$AV$29,2,0)=AF10,VLOOKUP(AF10&VLOOKUP(1,$AD$10:$AX$29,3,0),$AR$8:$AV$29,5,0)*100+VLOOKUP(AF10&VLOOKUP(1,$AD$10:$AX$29,3,0),$AR$8:$AV$29,3,0)*10)),0)+ _xlfn.IFNA(IF(AX10=VLOOKUP(2,$AW$10:$AX$29,2,0),IF(VLOOKUP(AF10&VLOOKUP(2,$AD$10:$AX$29,3,0),$AR$8:$AV$29,2,0)=AF10,VLOOKUP(AF10&VLOOKUP(2,$AD$10:$AX$29,3,0),$AR$8:$AV$29,5,0)*100+VLOOKUP(AF10&VLOOKUP(2,$AD$10:$AX$29,3,0),$AR$8:$AV$29,3,0)*10)),0)+ _xlfn.IFNA(IF(AX10=VLOOKUP(3,$AW$10:$AX$29,2,0),IF(VLOOKUP(AF10&VLOOKUP(3,$AD$10:$AX$29,3,0),$AR$8:$AV$29,2,0)=AF10,VLOOKUP(AF10&VLOOKUP(3,$AD$10:$AX$29,3,0),$AR$8:$AV$29,5,0)*100+VLOOKUP(AF10&VLOOKUP(3,$AD$10:$AX$29,3,0),$AR$8:$AV$29,3,0)*10)),0)+ _xlfn.IFNA(IF(AX10=VLOOKUP(4,$AW$10:$AX$29,2,0),IF(VLOOKUP(AF10&VLOOKUP(4,$AD$10:$AX$29,3,0),$AR$8:$AV$29,2,0)=AF10,VLOOKUP(AF10&VLOOKUP(4,$AD$10:$AX$29,3,0),$AR$8:$AV$29,5,0)*100+VLOOKUP(AF10&VLOOKUP(4,$AD$10:$AX$29,3,0),$AR$8:$AV$29,3,0)*10)),0)) -> 0 | BE10: =(IF(AND($AO$6>0,$BB$6>0),AN10*1000+AM10*100+AK10*10,0)+3)/100+BB10 -> 70079.03 | BF10: =RANK(BE10,$BE$10:$BE$29) -> 1 | BG10: =BE10-0.03 -> 70079 | BH10: =COUNTIF($BG$10:$BG$29,BG10) -> 1
A12: 7 | B12: 5 | C12: =VLOOKUP(A12,tDatos[],IF(UTCElegido="",3,12),0) -> 46186 | D12: =VLOOKUP(A12,tDatos[],IF(UTCElegido="",4,12),0) -> 0.875 | F12: =VLOOKUP(A12,tDatos[],5,0) -> HAITÍ | G12: =IF(AND(I12<>"",K12<>""),IF(I12=K12,"E",IF(I12>K12,"G","P")),"") -> P | I12: 0 | J12: - | K12: 2 | L12: =IF(AND(K12<>"",I12<>""),IF(K12=I12,"E",IF(K12>I12,"G","P")),"") -> G | N12: =VLOOKUP(A12,tDatos[],6,0) -> ESCOCIA | P12: =VLOOKUP(A12,tDatos[],9,0) -> Boston | AR12: =F12&N12 -> HAITÍESCOCIA | AS12: =IF(I12>K12,F12,IF(K12>I12,N12,"")) -> ESCOCIA | AT12: =I12 -> 0 | AU12: =K12 -> 2 | AV12: =AT12-AU12 -> -2
AR13: =N12&F12 -> ESCOCIAHAITÍ | AS13: =IF(I12>K12,F12,IF(K12>I12,N12,"")) -> ESCOCIA | AT13: =K12 -> 2 | AU13: =I12 -> 0 | AV13: =AT13-AU13 -> 2
R15: =" 2) " & VLOOKUP(2,$AE$10:$AF$29,2,0) -> 2) MARRUECOS | V15: =VLOOKUP(2,$AE$10:$AG$29,3,0) -> 3 | W15: =VLOOKUP(2,$AE$10:$AH$29,4,0) -> 2 | X15: =VLOOKUP(2,$AE$10:$AI$29,5,0) -> 1 | Y15: =VLOOKUP(2,$AE$10:$AJ$29,6,0) -> 0 | Z15: =VLOOKUP(2,$AE$10:$AK$29,7,0) -> 6 | AA15: =VLOOKUP(2,$AE$10:$AL$29,8,0) -> 2 | AB15: =Z15-AA15 -> 4 | AC15: =(W15*3)+X15 -> 7 | AD15: =RANK(AO15,$AO$10:$AO$29,0) -> 2 | AE15: =RANK(AP15,$AP$10:$AP$29,1) -> 2 | AF15: =N8 -> MARRUECOS | AG15: =3-COUNTIF(I33:K33,"") -> 3 | AH15: =COUNTIF(I33:K33,"G") -> 2 | AI15: =COUNTIF(I33:K33,"E") -> 1 | AJ15: =COUNTIF(I33:K33,"P") -> 0 | AK15: =SUM(K8,K16,I28) -> 6 | AL15: =SUM(I8,I16,K28) -> 2 | AM15: =AK15-AL15 -> 4 | AN15: =(AH15*3)+AI15*vcp -> 7 | AO15: =IF($AO$6>0,AN15*10+2) -> 72 | AP15: =IF(AF15=$R$38,BF15-100,IF(AF15=$R$37,BF15-200,IF(AF15=$R$36,BF15-300,BF15))) -> -198 | AQ15: =IF(R37="",IF(SUM($V$10:$V$29)>0,VLOOKUP(2,$AE$10:$AF$29,2,0),""),R37) -> MARRUECOS | AW15: =RANK(AY15,$AY$10:$AY$29,0) -> 2 | AX15: =IF(AND($AO$6>0,$AP$6>0),AN15*10000+AZ15,AO15) -> 70000 | AY15: =IF(AND($AO$6>0,$AP$6>0),AN15*10000+AZ15-1,AO15) -> 69999 | AZ15: =--IF(AND($AO$6>0,$AP$6>0), _xlfn.IFNA(IF(AN15=VLOOKUP(1,$AD$10:$AN$29,11,0),IF(VLOOKUP(AF15&VLOOKUP(1,$AD$10:$AN$29,3,0),$AR$8:$AS$29,2,0)=AF15,1000)),0)+ _xlfn.IFNA(IF(AN15=VLOOKUP(2,$AD$10:$AN$29,11,0),IF(VLOOKUP(AF15&VLOOKUP(2,$AD$10:$AN$29,3,0),$AR$8:$AS$29,2,0)=AF15,1000)),0)+ _xlfn.IFNA(IF(AN15=VLOOKUP(3,$AD$10:$AN$29,11,0),IF(VLOOKUP(AF15&VLOOKUP(3,$AD$10:$AN$29,3,0),$AR$8:$AS$29,2,0)=AF15,1000)),0)+ _xlfn.IFNA(IF(AN15=VLOOKUP(4,$AD$10:$AN$29,11,0),IF(VLOOKUP(AF15&VLOOKUP(4,$AD$10:$AN$29,3,0),$AR$8:$AS$29,2,0)=AF15,1000)),0)) -> 0 | BA15: =RANK(BB15,$BB$10:$BB$29,0) -> 1 | BB15: =AX15+BD15 -> 70000 | BC15: =AX15+BD15+2 -> 70002 | BD15: =--IF(AND($AO$6>0,$AX$6>0), _xlfn.IFNA(IF(AX15=VLOOKUP(1,$AW$10:$AX$29,2,0),IF(VLOOKUP(AF15&VLOOKUP(1,$AD$10:$AX$29,3,0),$AR$8:$AV$29,2,0)=AF15,VLOOKUP(AF15&VLOOKUP(1,$AD$10:$AX$29,3,0),$AR$8:$AV$29,5,0)*100+VLOOKUP(AF15&VLOOKUP(1,$AD$10:$AX$29,3,0),$AR$8:$AV$29,3,0)*10)),0)+ _xlfn.IFNA(IF(AX15=VLOOKUP(2,$AW$10:$AX$29,2,0),IF(VLOOKUP(AF15&VLOOKUP(2,$AD$10:$AX$29,3,0),$AR$8:$AV$29,2,0)=AF15,VLOOKUP(AF15&VLOOKUP(2,$AD$10:$AX$29,3,0),$AR$8:$AV$29,5,0)*100+VLOOKUP(AF15&VLOOKUP(2,$AD$10:$AX$29,3,0),$AR$8:$AV$29,3,0)*10)),0)+ _xlfn.IFNA(IF(AX15=VLOOKUP(3,$AW$10:$AX$29,2,0),IF(VLOOKUP(AF15&VLOOKUP(3,$AD$10:$AX$29,3,0),$AR$8:$AV$29,2,0)=AF15,VLOOKUP(AF15&VLOOKUP(3,$AD$10:$AX$29,3,0),$AR$8:$AV$29,5,0)*100+VLOOKUP(AF15&VLOOKUP(3,$AD$10:$AX$29,3,0),$AR$8:$AV$29,3,0)*10)),0)+ _xlfn.IFNA(IF(AX15=VLOOKUP(4,$AW$10:$AX$29,2,0),IF(VLOOKUP(AF15&VLOOKUP(4,$AD$10:$AX$29,3,0),$AR$8:$AV$29,2,0)=AF15,VLOOKUP(AF15&VLOOKUP(4,$AD$10:$AX$29,3,0),$AR$8:$AV$29,5,0)*100+VLOOKUP(AF15&VLOOKUP(4,$AD$10:$AX$29,3,0),$AR$8:$AV$29,3,0)*10)),0)) -> 0 | BE15: =(IF(AND($AO$6>0,$BB$6>0),AN15*1000+AM15*100+AK15*10,0)+2)/100+BB15 -> 70074.62 | BF15: =RANK(BE15,$BE$10:$BE$29) -> 2 | BG15: =BE15-0.02 -> 70074.6 | BH15: =COUNTIF($BG$10:$BG$29,BG15) -> 1
A16: 30 | B16: 30 | C16: =VLOOKUP(A16,tDatos[],IF(UTCElegido="",3,12),0) -> 46192 | D16: =VLOOKUP(A16,tDatos[],IF(UTCElegido="",4,12),0) -> 0.75 | F16: =VLOOKUP(A16,tDatos[],5,0) -> ESCOCIA | G16: =IF(AND(I16<>"",K16<>""),IF(I16=K16,"E",IF(I16>K16,"G","P")),"") -> P | I16: 1 | J16: - | K16: 3 | L16: =IF(AND(K16<>"",I16<>""),IF(K16=I16,"E",IF(K16>I16,"G","P")),"") -> G | N16: =VLOOKUP(A16,tDatos[],6,0) -> MARRUECOS | P16: =VLOOKUP(A16,tDatos[],9,0) -> Boston | AR16: =F16&N16 -> ESCOCIAMARRUECOS | AS16: =IF(I16>K16,F16,IF(K16>I16,N16,"")) -> MARRUECOS | AT16: =I16 -> 1 | AU16: =K16 -> 3 | AV16: =AT16-AU16 -> -2
AR17: =N16&F16 -> MARRUECOSESCOCIA | AS17: =IF(I16>K16,F16,IF(K16>I16,N16,"")) -> MARRUECOS | AT17: =K16 -> 3 | AU17: =I16 -> 1 | AV17: =AT17-AU17 -> 2
A20: 31 | B20: 29 | C20: =VLOOKUP(A20,tDatos[],IF(UTCElegido="",3,12),0) -> 46192 | D20: =VLOOKUP(A20,tDatos[],IF(UTCElegido="",4,12),0) -> 0.85416667 | F20: =VLOOKUP(A20,tDatos[],5,0) -> BRASIL | G20: =IF(AND(I20<>"",K20<>""),IF(I20=K20,"E",IF(I20>K20,"G","P")),"") -> G | I20: 5 | J20: - | K20: 0 | L20: =IF(AND(K20<>"",I20<>""),IF(K20=I20,"E",IF(K20>I20,"G","P")),"") -> P | N20: =VLOOKUP(A20,tDatos[],6,0) -> HAITÍ | P20: =VLOOKUP(A20,tDatos[],9,0) -> Filadelfia | R20: =" 3) " & VLOOKUP(3,$AE$10:$AF$29,2,0) -> 3) ESCOCIA | V20: =VLOOKUP(3,$AE$10:$AG$29,3,0) -> 3 | W20: =VLOOKUP(3,$AE$10:$AH$29,4,0) -> 1 | X20: =VLOOKUP(3,$AE$10:$AI$29,5,0) -> 0 | Y20: =VLOOKUP(3,$AE$10:$AJ$29,6,0) -> 2 | Z20: =VLOOKUP(3,$AE$10:$AK$29,7,0) -> 4 | AA20: =VLOOKUP(3,$AE$10:$AL$29,8,0) -> 7 | AB20: =Z20-AA20 -> -3 | AC20: =(W20*3)+X20 -> 3 | AD20: =RANK(AO20,$AO$10:$AO$29,0) -> 4 | AE20: =RANK(AP20,$AP$10:$AP$29,1) -> 4 | AF20: =F12 -> HAITÍ | AG20: =3-COUNTIF(I34:K34,"") -> 3 | AH20: =COUNTIF(I34:K34,"G") -> 0 | AI20: =COUNTIF(I34:K34,"E") -> 0 | AJ20: =COUNTIF(I34:K34,"P") -> 3 | AK20: =SUM(I12,K20,K28) -> 0 | AL20: =SUM(K12,I20,I28) -> 9 | AM20: =AK20-AL20 -> -9 | AN20: =(AH20*3)+AI20*vcp -> 0 | AO20: =IF($AO$6>0,AN20*10+1) -> 1 | AP20: =IF(AF20=$R$38,BF20-100,IF(AF20=$R$37,BF20-200,IF(AF20=$R$36,BF20-300,BF20))) -> 4 | AQ20: =IF(R38="",IF(SUM($V$10:$V$29)>0,VLOOKUP(3,$AE$10:$AF$29,2,0),""),R38) -> ESCOCIA | AR20: =F20&N20 -> BRASILHAITÍ | AS20: =IF(I20>K20,F20,IF(K20>I20,N20,"")) -> BRASIL | AT20: =I20 -> 5 | AU20: =K20 -> 0 | AV20: =AT20-AU20 -> 5 | AW20: =RANK(AY20,$AY$10:$AY$29,0) -> 4 | AX20: =IF(AND($AO$6>0,$AP$6>0),AN20*10000+AZ20,AO20) -> 0 | AY20: =IF(AND($AO$6>0,$AP$6>0),AN20*10000+AZ20-2,AO20) -> -2 | AZ20: =--IF(AND($AO$6>0,$AP$6>0), _xlfn.IFNA(IF(AN20=VLOOKUP(1,$AD$10:$AN$29,11,0),IF(VLOOKUP(AF20&VLOOKUP(1,$AD$10:$AN$29,3,0),$AR$8:$AS$29,2,0)=AF20,1000)),0)+ _xlfn.IFNA(IF(AN20=VLOOKUP(2,$AD$10:$AN$29,11,0),IF(VLOOKUP(AF20&VLOOKUP(2,$AD$10:$AN$29,3,0),$AR$8:$AS$29,2,0)=AF20,1000)),0)+ _xlfn.IFNA(IF(AN20=VLOOKUP(3,$AD$10:$AN$29,11,0),IF(VLOOKUP(AF20&VLOOKUP(3,$AD$10:$AN$29,3,0),$AR$8:$AS$29,2,0)=AF20,1000)),0)+ _xlfn.IFNA(IF(AN20=VLOOKUP(4,$AD$10:$AN$29,11,0),IF(VLOOKUP(AF20&VLOOKUP(4,$AD$10:$AN$29,3,0),$AR$8:$AS$29,2,0)=AF20,1000)),0)) -> 0 | BA20: =RANK(BB20,$BB$10:$BB$29,0) -> 4 | BB20: =AX20+BD20 -> 0 | BC20: =AX20+BD20+1 -> 1 | BD20: =--IF(AND($AO$6>0,$AX$6>0), _xlfn.IFNA(IF(AX20=VLOOKUP(1,$AW$10:$AX$29,2,0),IF(VLOOKUP(AF20&VLOOKUP(1,$AD$10:$AX$29,3,0),$AR$8:$AV$29,2,0)=AF20,VLOOKUP(AF20&VLOOKUP(1,$AD$10:$AX$29,3,0),$AR$8:$AV$29,5,0)*100+VLOOKUP(AF20&VLOOKUP(1,$AD$10:$AX$29,3,0),$AR$8:$AV$29,3,0)*10)),0)+ _xlfn.IFNA(IF(AX20=VLOOKUP(2,$AW$10:$AX$29,2,0),IF(VLOOKUP(AF20&VLOOKUP(2,$AD$10:$AX$29,3,0),$AR$8:$AV$29,2,0)=AF20,VLOOKUP(AF20&VLOOKUP(2,$AD$10:$AX$29,3,0),$AR$8:$AV$29,5,0)*100+VLOOKUP(AF20&VLOOKUP(2,$AD$10:$AX$29,3,0),$AR$8:$AV$29,3,0)*10)),0)+ _xlfn.IFNA(IF(AX20=VLOOKUP(3,$AW$10:$AX$29,2,0),IF(VLOOKUP(AF20&VLOOKUP(3,$AD$10:$AX$29,3,0),$AR$8:$AV$29,2,0)=AF20,VLOOKUP(AF20&VLOOKUP(3,$AD$10:$AX$29,3,0),$AR$8:$AV$29,5,0)*100+VLOOKUP(AF20&VLOOKUP(3,$AD$10:$AX$29,3,0),$AR$8:$AV$29,3,0)*10)),0)+ _xlfn.IFNA(IF(AX20=VLOOKUP(4,$AW$10:$AX$29,2,0),IF(VLOOKUP(AF20&VLOOKUP(4,$AD$10:$AX$29,3,0),$AR$8:$AV$29,2,0)=AF20,VLOOKUP(AF20&VLOOKUP(4,$AD$10:$AX$29,3,0),$AR$8:$AV$29,5,0)*100+VLOOKUP(AF20&VLOOKUP(4,$AD$10:$AX$29,3,0),$AR$8:$AV$29,3,0)*10)),0)) -> 0 | BE20: =(IF(AND($AO$6>0,$BB$6>0),AN20*1000+AM20*100+AK20*10,0)+1)/100+BB20 -> -8.99 | BF20: =RANK(BE20,$BE$10:$BE$29) -> 4 | BG20: =BE20-0.01 -> -9 | BH20: =COUNTIF($BG$10:$BG$29,BG20) -> 1
AR21: =N20&F20 -> HAITÍBRASIL | AS21: =IF(I20>K20,F20,IF(K20>I20,N20,"")) -> BRASIL | AT21: =K20 -> 0 | AU21: =I20 -> 5 | AV21: =AT21-AU21 -> -5
A24: 51 | B24: 49 | C24: =VLOOKUP(A24,tDatos[],IF(UTCElegido="",3,12),0) -> 46197 | D24: =VLOOKUP(A24,tDatos[],IF(UTCElegido="",4,12),0) -> 0.75 | F24: =VLOOKUP(A24,tDatos[],5,0) -> ESCOCIA | G24: =IF(AND(I24<>"",K24<>""),IF(I24=K24,"E",IF(I24>K24,"G","P")),"") -> P | I24: 1 | J24: - | K24: 4 | L24: =IF(AND(K24<>"",I24<>""),IF(K24=I24,"E",IF(K24>I24,"G","P")),"") -> G | N24: =VLOOKUP(A24,tDatos[],6,0) -> BRASIL | P24: =VLOOKUP(A24,tDatos[],9,0) -> Miami | AR24: =F24&N24 -> ESCOCIABRASIL | AS24: =IF(I24>K24,F24,IF(K24>I24,N24,"")) -> BRASIL | AT24: =I24 -> 1 | AU24: =K24 -> 4 | AV24: =AT24-AU24 -> -3
R25: =" 4) " & VLOOKUP(4,$AE$10:$AF$29,2,0) -> 4) HAITÍ | V25: =VLOOKUP(4,$AE$10:$AG$29,3,0) -> 3 | W25: =VLOOKUP(4,$AE$10:$AH$29,4,0) -> 0 | X25: =VLOOKUP(4,$AE$10:$AI$29,5,0) -> 0 | Y25: =VLOOKUP(4,$AE$10:$AJ$29,6,0) -> 3 | Z25: =VLOOKUP(4,$AE$10:$AK$29,7,0) -> 0 | AA25: =VLOOKUP(4,$AE$10:$AL$29,8,0) -> 9 | AB25: =Z25-AA25 -> -9 | AC25: =(W25*3)+X25 -> 0 | AD25: =RANK(AO25,$AO$10:$AO$29,0) -> 3 | AE25: =RANK(AP25,$AP$10:$AP$29,1) -> 3 | AF25: =N12 -> ESCOCIA | AG25: =3-COUNTIF(I35:K35,"") -> 3 | AH25: =COUNTIF(I35:K35,"G") -> 1 | AI25: =COUNTIF(I35:K35,"E") -> 0 | AJ25: =COUNTIF(I35:K35,"P") -> 2 | AK25: =SUM(K12,I16,I24) -> 4 | AL25: =SUM(I12,K16,K24) -> 7 | AM25: =AK25-AL25 -> -3 | AN25: =(AH25*3)+AI25*vcp -> 3 | AO25: =IF($AO$6>0,AN25*10) -> 30 | AP25: =IF(AF25=$R$38,BF25-100,IF(AF25=$R$37,BF25-200,IF(AF25=$R$36,BF25-300,BF25))) -> -97 | AQ25: =IF(SUM($V$10:$V$29)>0,VLOOKUP(4,$AE$10:$AF$29,2,0),"") -> HAITÍ | AR25: =N24&F24 -> BRASILESCOCIA | AS25: =IF(I24>K24,F24,IF(K24>I24,N24,"")) -> BRASIL | AT25: =K24 -> 4 | AU25: =I24 -> 1 | AV25: =AT25-AU25 -> 3 | AW25: =RANK(AY25,$AY$10:$AY$29,0) -> 3 | AX25: =IF(AND($AO$6>0,$AP$6>0),AN25*10000+AZ25,AO25) -> 30000 | AY25: =IF(AND($AO$6>0,$AP$6>0),AN25*10000+AZ25-3,AO25) -> 29997 | AZ25: =--IF(AND($AO$6>0,$AP$6>0), _xlfn.IFNA(IF(AN25=VLOOKUP(1,$AD$10:$AN$29,11,0),IF(VLOOKUP(AF25&VLOOKUP(1,$AD$10:$AN$29,3,0),$AR$8:$AS$29,2,0)=AF25,1000)),0)+ _xlfn.IFNA(IF(AN25=VLOOKUP(2,$AD$10:$AN$29,11,0),IF(VLOOKUP(AF25&VLOOKUP(2,$AD$10:$AN$29,3,0),$AR$8:$AS$29,2,0)=AF25,1000)),0)+ _xlfn.IFNA(IF(AN25=VLOOKUP(3,$AD$10:$AN$29,11,0),IF(VLOOKUP(AF25&VLOOKUP(3,$AD$10:$AN$29,3,0),$AR$8:$AS$29,2,0)=AF25,1000)),0)+ _xlfn.IFNA(IF(AN25=VLOOKUP(4,$AD$10:$AN$29,11,0),IF(VLOOKUP(AF25&VLOOKUP(4,$AD$10:$AN$29,3,0),$AR$8:$AS$29,2,0)=AF25,1000)),0)) -> 0 | BA25: =RANK(BB25,$BB$10:$BB$29,0) -> 3 | BB25: =AX25+BD25 -> 30000 | BC25: =AX25+BD25 -> 30000 | BD25: =--IF(AND($AO$6>0,$AX$6>0), _xlfn.IFNA(IF(AX25=VLOOKUP(1,$AW$10:$AX$29,2,0),IF(VLOOKUP(AF25&VLOOKUP(1,$AD$10:$AX$29,3,0),$AR$8:$AV$29,2,0)=AF25,VLOOKUP(AF25&VLOOKUP(1,$AD$10:$AX$29,3,0),$AR$8:$AV$29,5,0)*100+VLOOKUP(AF25&VLOOKUP(1,$AD$10:$AX$29,3,0),$AR$8:$AV$29,3,0)*10)),0)+ _xlfn.IFNA(IF(AX25=VLOOKUP(2,$AW$10:$AX$29,2,0),IF(VLOOKUP(AF25&VLOOKUP(2,$AD$10:$AX$29,3,0),$AR$8:$AV$29,2,0)=AF25,VLOOKUP(AF25&VLOOKUP(2,$AD$10:$AX$29,3,0),$AR$8:$AV$29,5,0)*100+VLOOKUP(AF25&VLOOKUP(2,$AD$10:$AX$29,3,0),$AR$8:$AV$29,3,0)*10)),0)+ _xlfn.IFNA(IF(AX25=VLOOKUP(3,$AW$10:$AX$29,2,0),IF(VLOOKUP(AF25&VLOOKUP(3,$AD$10:$AX$29,3,0),$AR$8:$AV$29,2,0)=AF25,VLOOKUP(AF25&VLOOKUP(3,$AD$10:$AX$29,3,0),$AR$8:$AV$29,5,0)*100+VLOOKUP(AF25&VLOOKUP(3,$AD$10:$AX$29,3,0),$AR$8:$AV$29,3,0)*10)),0)+ _xlfn.IFNA(IF(AX25=VLOOKUP(4,$AW$10:$AX$29,2,0),IF(VLOOKUP(AF25&VLOOKUP(4,$AD$10:$AX$29,3,0),$AR$8:$AV$29,2,0)=AF25,VLOOKUP(AF25&VLOOKUP(4,$AD$10:$AX$29,3,0),$AR$8:$AV$29,5,0)*100+VLOOKUP(AF25&VLOOKUP(4,$AD$10:$AX$29,3,0),$AR$8:$AV$29,3,0)*10)),0)) -> 0 | BE25: =IF(AND($AO$6>0,$BB$6>0),AN25*1000+AM25*100+AK25*10,0)/100+BB25 -> 30027.4 | BF25: =RANK(BE25,$BE$10:$BE$29) -> 3 | BG25: =BE25 -> 30027.4 | BH25: =COUNTIF($BG$10:$BG$29,BG25) -> 1
A28: 52 | B28: 50 | C28: =VLOOKUP(A28,tDatos[],IF(UTCElegido="",3,12),0) -> 46197 | D28: =VLOOKUP(A28,tDatos[],IF(UTCElegido="",4,12),0) -> 0.75 | F28: =VLOOKUP(A28,tDatos[],5,0) -> MARRUECOS | G28: =IF(AND(I28<>"",K28<>""),IF(I28=K28,"E",IF(I28>K28,"G","P")),"") -> G | I28: 2 | J28: - | K28: 0 | L28: =IF(AND(K28<>"",I28<>""),IF(K28=I28,"E",IF(K28>I28,"G","P")),"") -> P | N28: =VLOOKUP(A28,tDatos[],6,0) -> HAITÍ | P28: =VLOOKUP(A28,tDatos[],9,0) -> Atlanta | AR28: =F28&N28 -> MARRUECOSHAITÍ | AS28: =IF(I28>K28,F28,IF(K28>I28,N28,"")) -> MARRUECOS | AT28: =I28 -> 2 | AU28: =K28 -> 0 | AV28: =AT28-AU28 -> 2
AR29: =N28&F28 -> HAITÍMARRUECOS | AS29: =IF(I28>K28,F28,IF(K28>I28,N28,"")) -> MARRUECOS | AT29: =K28 -> 0 | AU29: =I28 -> 2 | AV29: =AT29-AU29 -> -2
R31: =IF(AO6=12,IF(BH31>4,"***¡ES NECESARIO DESEMPATAR MANUALMENTE!***",""),"") | BH31: =SUM(BH10:BH29) -> 4
F32: =F8 -> BRASIL | I32: =G8 -> E | J32: =G20 -> G | K32: =L24 -> G
F33: =N8 -> MARRUECOS | I33: =L8 -> E | J33: =L16 -> G | K33: =G28 -> G
F34: =F12 -> HAITÍ | I34: =G12 -> P | J34: =L20 -> P | K34: =L28 -> P
F35: =N12 -> ESCOCIA | I35: =L12 -> G | J35: =G16 -> P | K35: =G24 -> P
N36: Las posiciones se resuelven de forma automática en casi todos los casos. | Q36: Primer puesto: | R36: BRASIL
N37: Pero, de ser necesario, puedes determinar el orden manualmente: | Q37: Segundo puesto: | R37: MARRUECOS
Q38: Tercer puesto: | R38: ESCOCIA

Sheet D
B5: Los horarios de los partidos corresponden a la localidad donde se juega el encuentro.
B6: # | C6: Fechas | D6: Horas | E6: PARTIDOS | P6: Estadios | R6: POSICIONES | AO6: =COUNT(I8,K8,I12,K12,I16,K16,I20,K20,I24,K24,I28,K28) -> 12 | AP6: =(AN10=AN15)+(AN15=AN20)+(AN20=AN25)+(AN10=AN20)+(AN15=AN25)+(AN10=AN25) -> 0 | AR6: Partido | AS6: Ganador | AT6: 1 | AU6: 2 | AV6: Dif. | AX6: =(AX10=AX15)+(AX15=AX20)+(AX20=AX25)+(AX10=AX20)+(AX15=AX25)+(AX10=AX25) -> 0 | BB6: =(BB10=BB15)+(BB15=BB20)+(BB20=BB25)+(BB10=BB20)+(BB15=BB25)+(BB10=BB25) -> 0
AC7: Puntos
A8: 4 | B8: 4 | C8: =VLOOKUP(A8,tDatos[],IF(UTCElegido="",3,12),0) -> 46185 | D8: =VLOOKUP(A8,tDatos[],IF(UTCElegido="",4,12),0) -> 0.875 | F8: =VLOOKUP(A8,tDatos[],5,0) -> ESTADOS UNIDOS | G8: =IF(AND(I8<>"",K8<>""),IF(I8=K8,"E",IF(I8>K8,"G","P")),"") -> E | I8: 2 | J8: - | K8: 2 | L8: =IF(AND(K8<>"",I8<>""),IF(K8=I8,"E",IF(K8>I8,"G","P")),"") -> E | N8: =VLOOKUP(A8,tDatos[],6,0) -> PARAGUAY | P8: =VLOOKUP(A8,tDatos[],9,0) -> Los Angeles | V8: Jug. | W8: Gan. | X8: Emp. | Y8: Per. | Z8: GF | AA8: GC | AB8: DG | AG8: Jug. | AH8: Gan. | AI8: Emp. | AJ8: Per. | AK8: GF | AL8: GC | AM8: Dif. | AN8: Pts. | AR8: =F8&N8 -> ESTADOS UNIDOSPARAGUAY | AS8: =IF(I8>K8,F8,IF(K8>I8,N8,"")) | AT8: =I8 -> 2 | AU8: =K8 -> 2 | AV8: =AT8-AU8 -> 0
AR9: =N8&F8 -> PARAGUAYESTADOS UNIDOS | AS9: =IF(I8>K8,F8,IF(K8>I8,N8,"")) | AT9: =K8 -> 2 | AU9: =I8 -> 2 | AV9: =AT9-AU9 -> 0
